Workbook

Sheet 全量总表(0907)
A1: 点位基础信息 | C1: 界面分类信息 | L1: 空间分析信息 | AI1: 行人行为信息 | BJ1: 进一步计算
A2: 基本字段 | C2: ABCD 分类 | L2: 空间尺寸 | O2: 功能类型 | V2: 界面品质 | AE2: 环境舒适度 | AI2: 总体 | AM2: 年龄 | AQ2: 性别 | AT2: 动作 | AV2: 具体行为 | BL2: 辅助计算
A3: 序号 | B3: 完整地址 | C3: A 界面类型 | D3: B1 界面退让 | E3: B2 可视度 | F3: B3 构件延伸 a | G3: B3 构件延伸 b | H3: B3 构件延伸 c | I3: C 尺度层级 | J3: D 附属设施 | K3: D附属设施加权指数 | L3: 节点空间长度(m) | M3: 界面退让距离(m) | N3: 有效停留空间面积(㎡) | O3: 功能类型 | P3: 功能混合度 | Q3: 功能呈现度 | R3: 人均消费水平(元/人) | S3: 消费型停留空间占比(%) | T3: 可承载停留人数(人) | U3: 界面整体状态 | V3: 界面开放度 | W3: 临街互动性 | X3: 界面连续性 | Y3: 界面连续性照片 | Z3: 视觉丰富度 | AA3: 历史感知度 | AB3: 路面状态 | AC3: 动静混合度 | AD3: 动静混合度照片 | AE3: 遮荫来源 | AF3: 遮荫率(%) | AG3: 声环境舒适度 | AH3: 气味环境 | AI3: 行人样本数 | AJ3: 行为集群数 | AK3: 独立人数 | AL3: 集聚人数 | AM3: 幼年人数 | AN3: 青年人数 | AO3: 中年人数 | AP3: 老年人数 | AQ3: 男性人数 | AR3: 女性人数 | AS3: 无法判断性别人数 | AT3: 落座人数 | AU3: 站立/倚靠人数 | AV3: 观察人数 | AW3: 光顾人数 | AX3: 等待人数 | AY3: 打卡人数 | AZ3: 社交人数 | BA3: 争吵/纠纷人数 | BB3: 饮食人数 | BC3: 休憩人数 | BD3: 避雨/遮阳人数 | BE3: 工作人数 | BF3: 娱乐人数 | BG3: 运动人数 | BH3: 照看人数 | BI3: 整理人数 | BJ3: 总人数 | BK3: 停留密度 | BL3: 集聚比例 | BM3: H2 | BN3: I2 | BO3: J2 | BP3: K2 | BQ3: 香农原始指数 | BR3: 年龄混合度 | BS3: 居民指数 | BT3: 游客指数
A4: 11 | B4: 上海市徐汇区湖南路街道富民路291号 | C4: A2 商业界面 | D4: B1a 无后退 | E4: B2d 完全开敞 | G4: B3b-ii 招牌 | I4: C2 开间尺度（单个店面或小片连续界面） | J4: D1 公共座椅；D2 行道树；D6 共享单车 | K4: ==IF(TRIM(CLEAN(J4))="","",(IF(ISNUMBER(SEARCH("公共座椅",TRIM(CLEAN(J4)))),2,0)+IF(ISNUMBER(SEARCH("行道树",TRIM(CLEAN(J4)))),1,0)+IF(ISNUMBER(SEARCH("花坛",TRIM(CLEAN(J4)))),0.75,0)+IF(ISNUMBER(SEARCH("电线杆",TRIM(CLEAN(J4)))),0.4,0)+IF(ISNUMBER(SEARCH("路灯",TRIM(CLEAN(J4)))),0.45,0)+IF(ISNUMBER(SEARCH("共享单车",TRIM(CLEAN(J4)))),0.35,0)+IF(ISNUMBER(SEARCH("垃圾桶",TRIM(CLEAN(J4)))),-0.5,0))/(1+LN(1+(LEN(TRIM(CLEAN(J4)))-LEN(SUBSTITUTE(TRIM(CLEAN(J4)),";",""))+1)))) -> 1.978564 | L4: 27.2 | M4: 0 | N4: 106.8 | O4: 零售；文化展示 | P4: 2 | Q4: 5 | R4: 1157 | S4: 0 | T4: 50 | U4: 4 | V4: 3.7 | W4: 4 | X4: 极强连续性，左右均为相同界面风格的时尚大牌服装店 | Z4: 4 | AA4: 3.3 | AB4: 4 | AC4: 有抬升，砖石铺地，石制栏杆围合 | AE4: 树木 | AF4: 20 | AG4: 3.3 | AH4: 4 | AI4: 7 | AJ4: 3 | AK4: 1 | AL4: 6 | AM4: 0 | AN4: 7 | AO4: 0 | AP4: 0 | AQ4: 2 | AR4: 5 | AS4: 0 | AT4: 7 | AU4: 0 | AV4: 0 | AW4: 0 | AX4: 0 | AY4: 0 | AZ4: 0 | BA4: 0 | BB4: 2 | BC4: 7 | BD4: 0 | BE4: 0 | BF4: 0 | BG4: 0 | BH4: 0 | BI4: 0 | BJ4: ==AI4 -> 7 | BK4: ==BJ4/N4 -> 0.065543071 | BL4: ==AL4/AI4 -> 0.85714286 | BM4: ==IF(BJ4=0,0,AM4/BJ4) -> 0 | BN4: ==IF(BJ4=0,0,AN4/BJ4) -> 1 | BO4: ==IF(BJ4=0,0,AO4/BJ4) -> 0 | BP4: ==IF(BJ4=0,0,AP4/BJ4) -> 0 | BQ4: ==-IF(BM4=0,0,BM4*LN(BM4))-IF(BN4=0,0,BN4*LN(BN4))-IF(BO4=0,0,BO4*LN(BO4))-IF(BP4=0,0,BP4*LN(BP4)) -> 0 | BR4: ==IF(BJ4=0,0,BQ4/LN(4)*100) -> 0 | BS4: ==_xlfn.XLOOKUP(B4,点位均值!$A:$A,点位均值!$B:$B,"无匹配") -> 0.65448423 | BT4: ==_xlfn.XLOOKUP(B4,点位均值!$A:$A,点位均值!$C:$C,"无匹配") -> 2.8510257
A5: 35 | B5: 上海市徐汇区湖南路街道武康路98号 | C5: A4 基础设施界面 | D5: B1d 整体后退 | E5: B2a 仅仅墙面 | I5: C1 构件尺度（窗口、洞口、座椅） | J5: D1 公共座椅；D2 行道树 | K5: ==IF(TRIM(CLEAN(J5))="","",(IF(ISNUMBER(SEARCH("公共座椅",TRIM(CLEAN(J5)))),2,0)+IF(ISNUMBER(SEARCH("行道树",TRIM(CLEAN(J5)))),1,0)+IF(ISNUMBER(SEARCH("花坛",TRIM(CLEAN(J5)))),0.75,0)+IF(ISNUMBER(SEARCH("电线杆",TRIM(CLEAN(J5)))),0.4,0)+IF(ISNUMBER(SEARCH("路灯",TRIM(CLEAN(J5)))),0.45,0)+IF(ISNUMBER(SEARCH("共享单车",TRIM(CLEAN(J5)))),0.35,0)+IF(ISNUMBER(SEARCH("垃圾桶",TRIM(CLEAN(J5)))),-0.5,0))/(1+LN(1+(LEN(TRIM(CLEAN(J5)))-LEN(SUBSTITUTE(TRIM(CLEAN(J5)),";",""))+1)))) -> 1.7718483 | L5: 2.5 | M5: 0.5 | N5: 15 | O5: 公共服务 | P5: 1 | Q5: 5 | R5: 50 | S5: 0 | T5: 4 | U5: 5 | V5: 5 | W5: 5 | Z5: 3 | AA5: 1 | AB5: 5 | AE5: 树木 | AF5: 95 | AG5: 2 | AH5: 3 | AI5: 4 | AJ5: 2 | AK5: 0 | AL5: 4 | AM5: 1 | AN5: 2 | AO5: 1 | AP5: 0 | AQ5: 2 | AR5: 2 | AS5: 0 | AT5: 2 | AU5: 2 | AV5: 0 | AW5: 0 | AX5: 0 | AY5: 2 | AZ5: 0 | BA5: 0 | BB5: 0 | BC5: 2 | BD5: 0 | BE5: 0 | BF5: 0 | BG5: 0 | BH5: 1 | BI5: 0 | BJ5: ==AI5 -> 4 | BK5: ==BJ5/N5 -> 0.26666667 | BL5: ==AL5/AI5 -> 1 | BM5: ==IF(BJ5=0,0,AM5/BJ5) -> 0.25 | BN5: ==IF(BJ5=0,0,AN5/BJ5) -> 0.5 | BO5: ==IF(BJ5=0,0,AO5/BJ5) -> 0.25 | BP5: ==IF(BJ5=0,0,AP5/BJ5) -> 0 | BQ5: ==-IF(BM5=0,0,BM5*LN(BM5))-IF(BN5=0,0,BN5*LN(BN5))-IF(BO5=0,0,BO5*LN(BO5))-IF(BP5=0,0,BP5*LN(BP5)) -> 1.0397208 | BR5: ==IF(BJ5=0,0,BQ5/LN(4)*100) -> 75 | BS5: ==_xlfn.XLOOKUP(B5,点位均值!$A:$A,点位均值!$B:$B,"无匹配") -> 1.1358561 | BT5: ==_xlfn.XLOOKUP(B5,点位均值!$A:$A,点位均值!$C:$C,"无匹配") -> 3.1544386
A6: 112 | B6: 上海市徐汇区天平路街道襄阳南路215号 | C6: A2 商业界面 | D6: B1a 无后退 | E6: B2d 完全开敞 | F6: B3a-i 外摆在内侧 | I6: C2 开间尺度（单个店面或小片连续界面） | J6: D1 公共座椅；D4 电线杆；D5 路灯 | K6: ==IF(TRIM(CLEAN(J6))="","",(IF(ISNUMBER(SEARCH("公共座椅",TRIM(CLEAN(J6)))),2,0)+IF(ISNUMBER(SEARCH("行道树",TRIM(CLEAN(J6)))),1,0)+IF(ISNUMBER(SEARCH("花坛",TRIM(CLEAN(J6)))),0.75,0)+IF(ISNUMBER(SEARCH("电线杆",TRIM(CLEAN(J6)))),0.4,0)+IF(ISNUMBER(SEARCH("路灯",TRIM(CLEAN(J6)))),0.45,0)+IF(ISNUMBER(SEARCH("共享单车",TRIM(CLEAN(J6)))),0.35,0)+IF(ISNUMBER(SEARCH("垃圾桶",TRIM(CLEAN(J6)))),-0.5,0))/(1+LN(1+(LEN(TRIM(CLEAN(J6)))-LEN(SUBSTITUTE(TRIM(CLEAN(J6)),";",""))+1)))) -> 1.6832559 | L6: 3.5 | M6: 0 | N6: 20 | O6: 餐饮/饮品 | P6: 1 | Q6: 5 | R6: 109 | S6: 60 | T6: 30 | U6: 3.2 | V6: 3.2 | W6: 3 | X6: 与左侧的店面有极好的连续性，包括装修风格、店面大小都基本一致 | Y6: Image_1788254423307_739.jpg | Z6: 2.6 | AA6: 3 | AB6: 3.4 | AC6: 做了一级踏步抬升 | AD6: Image_1788254423307_739.jpg | AE6: 树木；其他 | AF6: 90 | AG6: 3.8 | AH6: 3.2 | AI6: 1 | AJ6: 1 | AK6: 0 | AL6: 1 | AM6: 0 | AN6: 1 | AO6: 0 | AP6: 0 | AQ6: 0 | AR6: 0 | AS6: 1 | AT6: 1 | AU6: 0 | AV6: 0 | AW6: 1 | AX6: 1 | AY6: 1 | AZ6: 1 | BA6: 0 | BB6: 0 | BC6: 0 | BD6: 0 | BE6: 0 | BF6: 0 | BG6: 0 | BH6: 0 | BI6: 0 | BJ6: ==AI6 -> 1 | BK6: ==BJ6/N6 -> 0.05 | BL6: ==AL6/AI6 -> 1 | BM6: ==IF(BJ6=0,0,AM6/BJ6) -> 0 | BN6: ==IF(BJ6=0,0,AN6/BJ6) -> 1 | BO6: ==IF(BJ6=0,0,AO6/BJ6) -> 0 | BP6: ==IF(BJ6=0,0,AP6/BJ6) -> 0 | BQ6: ==-IF(BM6=0,0,BM6*LN(BM6))-IF(BN6=0,0,BN6*LN(BN6))-IF(BO6=0,0,BO6*LN(BO6))-IF(BP6=0,0,BP6*LN(BP6)) -> 0 | BR6: ==IF(BJ6=0,0,BQ6/LN(4)*100) -> 0 | BS6: ==_xlfn.XLOOKUP(B6,点位均值!$A:$A,点位均值!$B:$B,"无匹配") -> 1.8687345 | BT6: ==_xlfn.XLOOKUP(B6,点位均值!$A:$A,点位均值!$C:$C,"无匹配") -> 8.9660574
A7: 33 | B7: 上海市徐汇区湖南路街道武康路57号 | C7: A4 基础设施界面 | D7: B1c 局部后退 | E7: B2a 仅仅墙面 | I7: C1 构件尺度（窗口、洞口、座椅） | J7: D1 公共座椅；D3 花坛 | K7: ==IF(TRIM(CLEAN(J7))="","",(IF(ISNUMBER(SEARCH("公共座椅",TRIM(CLEAN(J7)))),2,0)+IF(ISNUMBER(SEARCH("行道树",TRIM(CLEAN(J7)))),1,0)+IF(ISNUMBER(SEARCH("花坛",TRIM(CLEAN(J7)))),0.75,0)+IF(ISNUMBER(SEARCH("电线杆",TRIM(CLEAN(J7)))),0.4,0)+IF(ISNUMBER(SEARCH("路灯",TRIM(CLEAN(J7)))),0.45,0)+IF(ISNUMBER(SEARCH("共享单车",TRIM(CLEAN(J7)))),0.35,0)+IF(ISNUMBER(SEARCH("垃圾桶",TRIM(CLEAN(J7)))),-0.5,0))/(1+LN(1+(LEN(TRIM(CLEAN(J7)))-LEN(SUBSTITUTE(TRIM(CLEAN(J7)),";",""))+1)))) -> 1.6241943 | L7: 20 | M7: 2 | N7: 30 | O7: 餐饮/饮品 | P7: 2 | Q7: 4 | R7: 50 | S7: 50 | T7: 30 | U7: 5 | V7: 5 | W7: 5 | X7: / | Z7: 5 | AA7: 1 | AB7: 5 | AC7: / | AE7: 树木；建筑 | AF7: 80 | AG7: 4 | AH7: 4 | AI7: 16 | AJ7: 4 | AK7: 7 | AL7: 9 | AM7: 0 | AN7: 7 | AO7: 7 | AP7: 2 | AQ7: 16 | AR7: 0 | AS7: 0 | AT7: 5 | AU7: 11 | AV7: 6 | AW7: 0 | AX7: 1 | AY7: 9 | AZ7: 0 | BA7: 0 | BB7: 0 | BC7: 0 | BD7: 0 | BE7: 0 | BF7: 0 | BG7: 0 | BH7: 0 | BI7: 0 | BJ7: ==AI7 -> 16 | BK7: ==BJ7/N7 -> 0.53333333 | BL7: ==AL7/AI7 -> 0.5625 | BM7: ==IF(BJ7=0,0,AM7/BJ7) -> 0 | BN7: ==IF(BJ7=0,0,AN7/BJ7) -> 0.4375 | BO7: ==IF(BJ7=0,0,AO7/BJ7) -> 0.4375 | BP7: ==IF(BJ7=0,0,AP7/BJ7) -> 0.125 | BQ7: ==-IF(BM7=0,0,BM7*LN(BM7))-IF(BN7=0,0,BN7*LN(BN7))-IF(BO7=0,0,BO7*LN(BO7))-IF(BP7=0,0,BP7*LN(BP7)) -> 0.98327394 | BR7: ==IF(BJ7=0,0,BQ7/LN(4)*100) -> 70.928222 | BS7: ==_xlfn.XLOOKUP(B7,点位均值!$A:$A,点位均值!$B:$B,"无匹配") -> 0.28270782 | BT7: ==_xlfn.XLOOKUP(B7,点位均值!$A:$A,点位均值!$C:$C,"无匹配") -> 2.6283127
A8: 90 | B8: 上海市徐汇区天平路街道建国西路258号 | C8: A2 商业界面 | D8: B1d 整体后退 | E8: B2b 橱窗 | I8: C4 组团尺度（院落或街区） | J8: D2 行道树；D3 花坛；D4 电线杆 | K8: ==IF(TRIM(CLEAN(J8))="","",(IF(ISNUMBER(SEARCH("公共座椅",TRIM(CLEAN(J8)))),2,0)+IF(ISNUMBER(SEARCH("行道树",TRIM(CLEAN(J8)))),1,0)+IF(ISNUMBER(SEARCH("花坛",TRIM(CLEAN(J8)))),0.75,0)+IF(ISNUMBER(SEARCH("电线杆",TRIM(CLEAN(J8)))),0.5,0)+IF(ISNUMBER(SEARCH("路灯",TRIM(CLEAN(J8)))),0.5,0)+IF(ISNUMBER(SEARCH("共享单车",TRIM(CLEAN(J8)))),0.5,0)+IF(ISNUMBER(SEARCH("垃圾桶",TRIM(CLEAN(J8)))),-0.5,0))/(1+LN(1+(LEN(TRIM(CLEAN(J8)))-LEN(SUBSTITUTE(TRIM(CLEAN(J8)),";",""))+1)))) -> 1.3288862 | L8: 16 | M8: 1.5 | N8: 23 | O8: 餐饮/饮品 | P8: 1 | Q8: 4 | R8: 75 | S8: 70 | T8: 9 | U8: 4 | V8: 3 | W8: 4 | X8: 沿街建筑立面整体连续，老洋房围墙、院门错落排布，少量出入口打断界面 | Z8: 4 | AA8: 5 | AB8: 5 | AC8: 人行道铺地平整 | AE8: 树木；雨棚 | AF8: 70 | AG8: 4 | AH8: 4 | AI8: 2 | AJ8: 0 | AK8: 2 | AL8: 0 | AM8: 0 | AN8: 0 | AO8: 2 | AP8: 0 | AQ8: 2 | AR8: 0 | AS8: 0 | AT8: 0 | AU8: 2 | AV8: 0 | AW8: 0 | AX8: 0 | AY8: 0 | AZ8: 0 | BA8: 0 | BB8: 0 | BC8: 2 | BD8: 0 | BE8: 0 | BF8: 0 | BG8: 0 | BH8: 0 | BI8: 0 | BJ8: ==AI8 -> 2 | BK8: ==BJ8/N8 -> 0.086956522 | BL8: ==AL8/AI8 -> 0 | BM8: ==IF(BJ8=0,0,AM8/BJ8) -> 0 | BN8: ==IF(BJ8=0,0,AN8/BJ8) -> 0 | BO8: ==IF(BJ8=0,0,AO8/BJ8) -> 1 | BP8: ==IF(BJ8=0,0,AP8/BJ8) -> 0 | BQ8: ==-IF(BM8=0,0,BM8*LN(BM8))-IF(BN8=0,0,BN8*LN(BN8))-IF(BO8=0,0,BO8*LN(BO8))-IF(BP8=0,0,BP8*LN(BP8)) -> 0 | BR8: ==IF(BJ8=0,0,BQ8/LN(4)*100) -> 0 | BS8: ==_xlfn.XLOOKUP(B8,点位均值!$A:$A,点位均值!$B:$B,"无匹配") -> 1.2791563 | BT8: ==_xlfn.XLOOKUP(B8,点位均值!$A:$A,点位均值!$C:$C,"无匹配") -> 1.3665796
A9: 43 | B9: 上海市徐汇区湖南路街道武康路378号 | C9: A2 商业界面 | D9: B1d 整体后退 | E9: B2b 橱窗 | F9: B3a-ii 外摆在外侧 | G9: B3c 围栏 | I9: C3 建筑尺度（整栋建筑） | J9: D2 行道树；D4 电线杆；D5 路灯 | K9: ==IF(TRIM(CLEAN(J9))="","",(IF(ISNUMBER(SEARCH("公共座椅",TRIM(CLEAN(J9)))),2,0)+IF(ISNUMBER(SEARCH("行道树",TRIM(CLEAN(J9)))),1,0)+IF(ISNUMBER(SEARCH("花坛",TRIM(CLEAN(J9)))),0.75,0)+IF(ISNUMBER(SEARCH("电线杆",TRIM(CLEAN(J9)))),0.5,0)+IF(ISNUMBER(SEARCH("路灯",TRIM(CLEAN(J9)))),0.5,0)+IF(ISNUMBER(SEARCH("共享单车",TRIM(CLEAN(J9)))),0.5,0)+IF(ISNUMBER(SEARCH("垃圾桶",TRIM(CLEAN(J9)))),-0.5,0))/(1+LN(1+(LEN(TRIM(CLEAN(J9)))-LEN(SUBSTITUTE(TRIM(CLEAN(J9)),";",""))+1)))) -> 1.1812322 | L9: 10 | M9: 46085 | O9: 餐饮/饮品；其他 | P9: 3 | Q9: 5 | U9: 5 | V9: 5 | W9: 4 | Z9: 4 | AA9: 2 | AB9: 4 | AE9: 树木；建筑 | AI9: 11 | AJ9: 2 | AK9: 0 | AL9: 11 | AM9: 0 | AN9: 2 | AO9: 9 | AP9: 0 | AQ9: 9 | AR9: 2 | AS9: 0 | AT9: 11 | AU9: 0 | AV9: 0 | AW9: 0 | AX9: 0 | AY9: 0 | AZ9: 0 | BA9: 0 | BB9: 0 | BC9: 11 | BD9: 0 | BE9: 0 | BF9: 0 | BG9: 0 | BH9: 0 | BI9: 0 | BJ9: ==AI9 -> 11 | BK9: ==BJ9/N9 -> #DIV/0! | BL9: ==AL9/AI9 -> 1 | BM9: ==IF(BJ9=0,0,AM9/BJ9) -> 0 | BN9: ==IF(BJ9=0,0,AN9/BJ9) -> 0.18181818 | BO9: ==IF(BJ9=0,0,AO9/BJ9) -> 0.81818182 | BP9: ==IF(BJ9=0,0,AP9/BJ9) -> 0 | BQ9: ==-IF(BM9=0,0,BM9*LN(BM9))-IF(BN9=0,0,BN9*LN(BN9))-IF(BO9=0,0,BO9*LN(BO9))-IF(BP9=0,0,BP9*LN(BP9)) -> 0.47413931 | BR9: ==IF(BJ9=0,0,BQ9/LN(4)*100) -> 34.201922 | BS9: ==_xlfn.XLOOKUP(B9,点位均值!$A:$A,点位均值!$B:$B,"无匹配") -> 1.1451613 | BT9: ==_xlfn.XLOOKUP(B9,点位均值!$A:$A,点位均值!$C:$C,"无匹配") -> 1.5075718
A10: 132 | B10: 上海市徐汇区天平路街道永康路43号 | C10: A2 商业界面 | D10: B1a 无后退 | E10: B2b 橱窗 | F10: B3a-ii 外摆在外侧 | G10: B3b-i 雨棚 | I10: C2 开间尺度（单个店面或小片连续界面） | J10: D1 公共座椅 | K10: ==IF(TRIM(CLEAN(J10))="","",(IF(ISNUMBER(SEARCH("公共座椅",TRIM(CLEAN(J10)))),2,0)+IF(ISNUMBER(SEARCH("行道树",TRIM(CLEAN(J10)))),1,0)+IF(ISNUMBER(SEARCH("花坛",TRIM(CLEAN(J10)))),0.75,0)+IF(ISNUMBER(SEARCH("电线杆",TRIM(CLEAN(J10)))),0.4,0)+IF(ISNUMBER(SEARCH("路灯",TRIM(CLEAN(J10)))),0.45,0)+IF(ISNUMBER(SEARCH("共享单车",TRIM(CLEAN(J10)))),0.35,0)+IF(ISNUMBER(SEARCH("垃圾桶",TRIM(CLEAN(J10)))),-0.5,0))/(1+LN(1+(LEN(TRIM(CLEAN(J10)))-LEN(SUBSTITUTE(TRIM(CLEAN(J10)),";",""))+1)))) -> 1.1812322 | L10: 15 | M10: 0.5 | N10: 10 | O10: 餐饮/饮品；文化展示 | P10: 2 | Q10: 5 | R10: 41 | S10: 80 | T10: 10 | U10: 4 | V10: 4 | W10: 5 | X10: 与两侧建筑连续性很好 | Y10: IMG_20260825_114013.jpg | Z10: 5 | AA10: 4 | AB10: 5 | AC10: 做了很小的一级踏步抬升 | AD10: IMG_20260825_114013.jpg | AE10: 建筑 | AF10: 50 | AG10: 4 | AH10: 4 | AI10: 8 | AJ10: 0 | AK10: 8 | AL10: 0 | AM10: 0 | AN10: 8 | AO10: 0 | AP10: 0 | AQ10: 1 | AR10: 7 | AS10: 0 | AT10: 0 | AU10: 8 | AV10: 0 | AW10: 4 | AX10: 0 | AY10: 8 | AZ10: 0 | BA10: 0 | BB10: 0 | BC10: 0 | BD10: 0 | BE10: 0 | BF10: 0 | BG10: 0 | BH10: 0 | BI10: 0 | BJ10: ==AI10 -> 8 | BK10: ==BJ10/N10 -> 0.8 | BL10: ==AL10/AI10 -> 0 | BM10: ==IF(BJ10=0,0,AM10/BJ10) -> 0 | BN10: ==IF(BJ10=0,0,AN10/BJ10) -> 1 | BO10: ==IF(BJ10=0,0,AO10/BJ10) -> 0 | BP10: ==IF(BJ10=0,0,AP10/BJ10) -> 0 | BQ10: ==-IF(BM10=0,0,BM10*LN(BM10))-IF(BN10=0,0,BN10*LN(BN10))-IF(BO10=0,0,BO10*LN(BO10))-IF(BP10=0,0,BP10*LN(BP10)) -> 0 | BR10: ==IF(BJ10=0,0,BQ10/LN(4)*100) -> 0 | BS10: ==_xlfn.XLOOKUP(B10,点位均值!$A:$A,点位均值!$B:$B,"无匹配") -> 0.34565757 | BT10: ==_xlfn.XLOOKUP(B10,点位均值!$A:$A,点位均值!$C:$C,"无匹配") -> 5.0370757
A11: 10 | B11: 上海市徐汇区湖南路街道汾阳路64弄2号 | C11: A2 商业界面 | D11: B1a 无后退 | E11: B2b 橱窗 | F11: B3a-ii 外摆在外侧 | I11: C2 开间尺度（单个店面或小片连续界面） | J11: D2 行道树；D4 电线杆；D5 路灯 | K11: ==IF(TRIM(CLEAN(J11))="","",(IF(ISNUMBER(SEARCH("公共座椅",TRIM(CLEAN(J11)))),2,0)+IF(ISNUMBER(SEARCH("行道树",TRIM(CLEAN(J11)))),1,0)+IF(ISNUMBER(SEARCH("花坛",TRIM(CLEAN(J11)))),0.75,0)+IF(ISNUMBER(SEARCH("电线杆",TRIM(CLEAN(J11)))),0.4,0)+IF(ISNUMBER(SEARCH("路灯",TRIM(CLEAN(J11)))),0.45,0)+IF(ISNUMBER(SEARCH("共享单车",TRIM(CLEAN(J11)))),0.35,0)+IF(ISNUMBER(SEARCH("垃圾桶",TRIM(CLEAN(J11)))),-0.5,0))/(1+LN(1+(LEN(TRIM(CLEAN(J11)))-LEN(SUBSTITUTE(TRIM(CLEAN(J11)),";",""))+1)))) -> 1.0926398 | L11: 21 | M11: 0 | N11: 24 | O11: 餐饮/饮品 | P11: 2 | Q11: 3 | R11: 118 | S11: 100 | T11: 20 | U11: 1 | V11: 3 | W11: 3 | X11: 独立独栋建筑 | Z11: 4 | AA11: 4 | AB11: 5 | AC11: 无特殊处理 | AE11: 树木；建筑 | AF11: 60 | AG11: 4 | AH11: 4 | AI11: 4 | AJ11: 4 | AK11: 0 | AL11: 4 | AM11: 1 | AN11: 0 | AO11: 1 | AP11: 2 | AQ11: 1 | AR11: 3 | AS11: 0 | AT11: 2 | AU11: 2 | AV11: 0 | AW11: 0 | AX11: 2 | AY11: 0 | AZ11: 2 | BA11: 0 | BB11: 0 | BC11: 2 | BD11: 0 | BE11: 0 | BF11: 0 | BG11: 0 | BH11: 0 | BI11: 0 | BJ11: ==AI11 -> 4 | BK11: ==BJ11/N11 -> 0.16666667 | BL11: ==AL11/AI11 -> 1 | BM11: ==IF(BJ11=0,0,AM11/BJ11) -> 0.25 | BN11: ==IF(BJ11=0,0,AN11/BJ11) -> 0 | BO11: ==IF(BJ11=0,0,AO11/BJ11) -> 0.25 | BP11: ==IF(BJ11=0,0,AP11/BJ11) -> 0.5 | BQ11: ==-IF(BM11=0,0,BM11*LN(BM11))-IF(BN11=0,0,BN11*LN(BN11))-IF(BO11=0,0,BO11*LN(BO11))-IF(BP11=0,0,BP11*LN(BP11)) -> 1.0397208 | BR11: ==IF(BJ11=0,0,BQ11/LN(4)*100) -> 75 | BS11: ==_xlfn.XLOOKUP(B11,点位均值!$A:$A,点位均值!$B:$B,"无匹配") -> 3.8462779 | BT11: ==_xlfn.XLOOKUP(B11,点位均值!$A:$A,点位均值!$C:$C,"无匹配") -> 1.2244125
A12: 49 | B12: 上海市徐汇区湖南路街道新乐路144号 | C12: A2 商业界面 | D12: B1b 区域后退 | E12: B2c 墙面开洞 | I12: C2 开间尺度（单个店面或小片连续界面） | J12: D2 行道树；D4 电线杆；D5 路灯 | K12: ==IF(TRIM(CLEAN(J12))="","",(IF(ISNUMBER(SEARCH("公共座椅",TRIM(CLEAN(J12)))),2,0)+IF(ISNUMBER(SEARCH("行道树",TRIM(CLEAN(J12)))),1,0)+IF(ISNUMBER(SEARCH("花坛",TRIM(CLEAN(J12)))),0.75,0)+IF(ISNUMBER(SEARCH("电线杆",TRIM(CLEAN(J12)))),0.4,0)+IF(ISNUMBER(SEARCH("路灯",TRIM(CLEAN(J12)))),0.45,0)+IF(ISNUMBER(SEARCH("共享单车",TRIM(CLEAN(J12)))),0.35,0)+IF(ISNUMBER(SEARCH("垃圾桶",TRIM(CLEAN(J12)))),-0.5,0))/(1+LN(1+(LEN(TRIM(CLEAN(J12)))-LEN(SUBSTITUTE(TRIM(CLEAN(J12)),";",""))+1)))) -> 1.0926398 | L12: 3.5 | M12: 0 | N12: 4.3 | O12: 零售 | P12: 1 | Q12: 4 | R12: 500 | S12: 0 | T12: 0 | U12: 5 | V12: 4 | W12: 4 | X12: 不连续，左侧断开（小区出入口） | Y12: photo (4).jpg | Z12: 5 | AA12: 4 | AB12: 5 | AC12: 停留拍照打卡为主；铺地变化；平地；开敞 | AD12: photo (4).jpg | AE12: 树木 | AF12: 60 | AG12: 4 | AH12: 5 | AI12: 10 | AJ12: 5 | AK12: 0 | AL12: 10 | AM12: 0 | AN12: 10 | AO12: 0 | AP12: 0 | AQ12: 3 | AR12: 7 | AS12: 0 | AT12: 0 | AU12: 10 | AV12: 8 | AW12: 0 | AX12: 0 | AY12: 10 | AZ12: 2 | BA12: 0 | BB12: 0 | BC12: 0 | BD12: 0 | BE12: 0 | BF12: 0 | BG12: 0 | BH12: 0 | BI12: 0 | BJ12: ==AI12 -> 10 | BK12: ==BJ12/N12 -> 2.3255814 | BL12: ==AL12/AI12 -> 1 | BM12: ==IF(BJ12=0,0,AM12/BJ12) -> 0 | BN12: ==IF(BJ12=0,0,AN12/BJ12) -> 1 | BO12: ==IF(BJ12=0,0,AO12/BJ12) -> 0 | BP12: ==IF(BJ12=0,0,AP12/BJ12) -> 0 | BQ12: ==-IF(BM12=0,0,BM12*LN(BM12))-IF(BN12=0,0,BN12*LN(BN12))-IF(BO12=0,0,BO12*LN(BO12))-IF(BP12=0,0,BP12*LN(BP12)) -> 0 | BR12: ==IF(BJ12=0,0,BQ12/LN(4)*100) -> 0 | BS12: ==_xlfn.XLOOKUP(B12,点位均值!$A:$A,点位均值!$B:$B,"无匹配") -> 0.41444169 | BT12: ==_xlfn.XLOOKUP(B12,点位均值!$A:$A,点位均值!$C:$C,"无匹配") -> 6.8154569
A13: 50 | B13: 上海市徐汇区湖南路街道新乐路158号 | C13: A2 商业界面 | D13: B1b 区域后退 | E13: B2d 完全开敞 | I13: C2 开间尺度（单个店面或小片连续界面） | J13: D2 行道树；D4 电线杆；D5 路灯 | K13: ==IF(TRIM(CLEAN(J13))="","",(IF(ISNUMBER(SEARCH("公共座椅",TRIM(CLEAN(J13)))),2,0)+IF(ISNUMBER(SEARCH("行道树",TRIM(CLEAN(J13)))),1,0)+IF(ISNUMBER(SEARCH("花坛",TRIM(CLEAN(J13)))),0.75,0)+IF(ISNUMBER(SEARCH("电线杆",TRIM(CLEAN(J13)))),0.4,0)+IF(ISNUMBER(SEARCH("路灯",TRIM(CLEAN(J13)))),0.45,0)+IF(ISNUMBER(SEARCH("共享单车",TRIM(CLEAN(J13)))),0.35,0)+IF(ISNUMBER(SEARCH("垃圾桶",TRIM(CLEAN(J13)))),-0.5,0))/(1+LN(1+(LEN(TRIM(CLEAN(J13)))-LEN(SUBSTITUTE(TRIM(CLEAN(J13)),";",""))+1)))) -> 1.0926398 | L13: 16.4 | M13: 1.5 | N13: 47.4 | O13: 零售 | P13: 1 | Q13: 1 | S13: 0 | T13: 6 | U13: 3 | V13: 4 | W13: 4 | X13: 连续 | Y13: photo (5).jpg | Z13: 3 | AA13: 1 | AB13: 5 | AC13: 通行与停留并存；铺地统一；有明显高差（台阶）；开敞 | AD13: photo (5).jpg | AE13: 树木；建筑 | AF13: 30 | AG13: 4 | AH13: 3 | AI13: 6 | AJ13: 2 | AK13: 2 | AL13: 4 | AM13: 0 | AN13: 5 | AO13: 1 | AP13: 0 | AQ13: 1 | AR13: 4 | AS13: 1 | AT13: 6 | AU13: 0 | AV13: 0 | AW13: 0 | AX13: 0 | AY13: 0 | AZ13: 0 | BA13: 0 | BB13: 0 | BC13: 6 | BD13: 4 | BE13: 0 | BF13: 0 | BG13: 0 | BH13: 0 | BI13: 0 | BJ13: ==AI13 -> 6 | BK13: ==BJ13/N13 -> 0.12658228 | BL13: ==AL13/AI13 -> 0.66666667 | BM13: ==IF(BJ13=0,0,AM13/BJ13) -> 0 | BN13: ==IF(BJ13=0,0,AN13/BJ13) -> 0.83333333 | BO13: ==IF(BJ13=0,0,AO13/BJ13) -> 0.16666667 | BP13: ==IF(BJ13=0,0,AP13/BJ13) -> 0 | BQ13: ==-IF(BM13=0,0,BM13*LN(BM13))-IF(BN13=0,0,BN13*LN(BN13))-IF(BO13=0,0,BO13*LN(BO13))-IF(BP13=0,0,BP13*LN(BP13)) -> 0.45056121 | BR13: ==IF(BJ13=0,0,BQ13/LN(4)*100) -> 32.501121 | BS13: ==_xlfn.XLOOKUP(B13,点位均值!$A:$A,点位均值!$B:$B,"无匹配") -> 0.99255583 | BT13: ==_xlfn.XLOOKUP(B13,点位均值!$A:$A,点位均值!$C:$C,"无匹配") -> 3.3913838
A14: 65 | B14: 上海市静安区南京西路街道巨鹿路691号 | C14: A2 商业界面 | D14: B1a 无后退 | E14: B2d 完全开敞 | F14: B3a-i 外摆在内侧 | I14: C2 开间尺度（单个店面或小片连续界面） | J14: D2 行道树；D4 电线杆；D5 路灯 | K14: ==IF(TRIM(CLEAN(J14))="","",(IF(ISNUMBER(SEARCH("公共座椅",TRIM(CLEAN(J14)))),2,0)+IF(ISNUMBER(SEARCH("行道树",TRIM(CLEAN(J14)))),1,0)+IF(ISNUMBER(SEARCH("花坛",TRIM(CLEAN(J14)))),0.75,0)+IF(ISNUMBER(SEARCH("电线杆",TRIM(CLEAN(J14)))),0.4,0)+IF(ISNUMBER(SEARCH("路灯",TRIM(CLEAN(J14)))),0.45,0)+IF(ISNUMBER(SEARCH("共享单车",TRIM(CLEAN(J14)))),0.35,0)+IF(ISNUMBER(SEARCH("垃圾桶",TRIM(CLEAN(J14)))),-0.5,0))/(1+LN(1+(LEN(TRIM(CLEAN(J14)))-LEN(SUBSTITUTE(TRIM(CLEAN(J14)),";",""))+1)))) -> 1.0926398 | L14: 23 | M14: 0 | N14: 73 | O14: 餐饮/饮品 | P14: 2 | Q14: 5 | R14: 100 | S14: 70 | T14: 4 | U14: 3 | V14: 4 | W14: 4 | X14: 界面不连续，入口等有退让 | Y14: IMG_5844.jpg | Z14: 3 | AA14: 4 | AB14: 4 | AC14: 外摆座椅停留，无特殊铺地、抬升、围合 | AD14: IMG_5844.jpg | AE14: 树木；雨棚 | AF14: 80 | AG14: 3 | AH14: 3 | AI14: 3 | AJ14: 1 | AK14: 1 | AL14: 2 | AM14: 1 | AN14: 0 | AO14: 2 | AP14: 0 | AQ14: 1 | AR14: 2 | AS14: 0 | AT14: 3 | AU14: 0 | AV14: 0 | AW14: 0 | AX14: 0 | AY14: 0 | AZ14: 2 | BA14: 0 | BB14: 0 | BC14: 3 | BD14: 0 | BE14: 0 | BF14: 0 | BG14: 0 | BH14: 0 | BI14: 0 | BJ14: ==AI14 -> 3 | BK14: ==BJ14/N14 -> 0.04109589 | BL14: ==AL14/AI14 -> 0.66666667 | BM14: ==IF(BJ14=0,0,AM14/BJ14) -> 0.33333333 | BN14: ==IF(BJ14=0,0,AN14/BJ14) -> 0 | BO14: ==IF(BJ14=0,0,AO14/BJ14) -> 0.66666667 | BP14: ==IF(BJ14=0,0,AP14/BJ14) -> 0 | BQ14: ==-IF(BM14=0,0,BM14*LN(BM14))-IF(BN14=0,0,BN14*LN(BN14))-IF(BO14=0,0,BO14*LN(BO14))-IF(BP14=0,0,BP14*LN(BP14)) -> 0.63651417 | BR14: ==IF(BJ14=0,0,BQ14/LN(4)*100) -> 45.914792 | BS14: ==_xlfn.XLOOKUP(B14,点位均值!$A:$A,点位均值!$B:$B,"无匹配") -> 3.6538462 | BT14: ==_xlfn.XLOOKUP(B14,点位均值!$A:$A,点位均值!$C:$C,"无匹配") -> 2.3143603
A15: 101 | B15: 上海市徐汇区天平路街道太原路76号 | C15: A2 商业界面 | D15: B1a 无后退 | E15: B2b 橱窗 | F15: B3a-i 外摆在内侧 | I15: C3 建筑尺度（整栋建筑） | J15: D2 行道树；D4 电线杆；D5 路灯 | K15: ==IF(TRIM(CLEAN(J15))="","",(IF(ISNUMBER(SEARCH("公共座椅",TRIM(CLEAN(J15)))),2,0)+IF(ISNUMBER(SEARCH("行道树",TRIM(CLEAN(J15)))),1,0)+IF(ISNUMBER(SEARCH("花坛",TRIM(CLEAN(J15)))),0.75,0)+IF(ISNUMBER(SEARCH("电线杆",TRIM(CLEAN(J15)))),0.4,0)+IF(ISNUMBER(SEARCH("路灯",TRIM(CLEAN(J15)))),0.45,0)+IF(ISNUMBER(SEARCH("共享单车",TRIM(CLEAN(J15)))),0.35,0)+IF(ISNUMBER(SEARCH("垃圾桶",TRIM(CLEAN(J15)))),-0.5,0))/(1+LN(1+(LEN(TRIM(CLEAN(J15)))-LEN(SUBSTITUTE(TRIM(CLEAN(J15)),";",""))+1)))) -> 1.0926398 | L15: 24 | M15: 0 | N15: 48 | O15: 零售 | P15: 3 | Q15: 4 | R15: 15 | S15: 40 | T15: 15 | U15: 3.5 | V15: 4 | W15: 3.5 | X15: 处于街角，风格一致 | Z15: 3 | AA15: 3 | AB15: 3.5 | AC15: 人行道平整，铺地无变化 | AE15: 树木 | AF15: 40 | AG15: 2.5 | AH15: 2.5 | AI15: 12 | AJ15: 3 | AK15: 4 | AL15: 8 | AM15: 1 | AN15: 9 | AO15: 1 | AP15: 1 | AQ15: 6 | AR15: 6 | AS15: 0 | AT15: 1 | AU15: 11 | AV15: 0 | AW15: 2 | AX15: 0 | AY15: 9 | AZ15: 0 | BA15: 0 | BB15: 1 | BC15: 0 | BD15: 0 | BE15: 0 | BF15: 0 | BG15: 0 | BH15: 0 | BI15: 0 | BJ15: ==AI15 -> 12 | BK15: ==BJ15/N15 -> 0.25 | BL15: ==AL15/AI15 -> 0.66666667 | BM15: ==IF(BJ15=0,0,AM15/BJ15) -> 0.083333333 | BN15: ==IF(BJ15=0,0,AN15/BJ15) -> 0.75 | BO15: ==IF(BJ15=0,0,AO15/BJ15) -> 0.083333333 | BP15: ==IF(BJ15=0,0,AP15/BJ15) -> 0.083333333 | BQ15: ==-IF(BM15=0,0,BM15*LN(BM15))-IF(BN15=0,0,BN15*LN(BN15))-IF(BO15=0,0,BO15*LN(BO15))-IF(BP15=0,0,BP15*LN(BP15)) -> 0.83698822 | BR15: ==IF(BJ15=0,0,BQ15/LN(4)*100) -> 60.375937 | BS15: ==_xlfn.XLOOKUP(B15,点位均值!$A:$A,点位均值!$B:$B,"无匹配") -> 0.23920596 | BT15: ==_xlfn.XLOOKUP(B15,点位均值!$A:$A,点位均值!$C:$C,"无匹配") -> 3.2449086
A16: 124 | B16: 上海市徐汇区天平路街道襄阳南路391号 | C16: A2 商业界面 | D16: B1c 局部后退 | E16: B2b 橱窗 | F16: B3a-ii 外摆在外侧 | G16: B3b-i 雨棚 | I16: C2 开间尺度（单个店面或小片连续界面） | J16: D2 行道树；D5 路灯；D6 共享单车 | K16: ==IF(TRIM(CLEAN(J16))="","",(IF(ISNUMBER(SEARCH("公共座椅",TRIM(CLEAN(J16)))),2,0)+IF(ISNUMBER(SEARCH("行道树",TRIM(CLEAN(J16)))),1,0)+IF(ISNUMBER(SEARCH("花坛",TRIM(CLEAN(J16)))),0.75,0)+IF(ISNUMBER(SEARCH("电线杆",TRIM(CLEAN(J16)))),0.4,0)+IF(ISNUMBER(SEARCH("路灯",TRIM(CLEAN(J16)))),0.45,0)+IF(ISNUMBER(SEARCH("共享单车",TRIM(CLEAN(J16)))),0.35,0)+IF(ISNUMBER(SEARCH("垃圾桶",TRIM(CLEAN(J16)))),-0.5,0))/(1+LN(1+(LEN(TRIM(CLEAN(J16)))-LEN(SUBSTITUTE(TRIM(CLEAN(J16)),";",""))+1)))) -> 1.063109 | L16: 5 | M16: 0.5 | N16: 2.5 | O16: 餐饮/饮品；零售 | P16: 1 | Q16: 3 | R16: 142 | S16: 100 | T16: 2 | U16: 3.8 | V16: 3.6 | W16: 3.4 | X16: 独立建筑，连续性一般 | Y16: IMG_20260901_171615.jpg | Z16: 3.6 | AA16: 3.8 | AB16: 3.4 | AC16: 一级踏步抬升 | AD16: IMG_20260901_171622.jpg | AE16: 树木；雨棚 | AF16: 80 | AG16: 3.8 | AH16: 3.6 | AI16: 12 | AJ16: 3 | AK16: 4 | AL16: 8 | AM16: 0 | AN16: 6 | AO16: 3 | AP16: 3 | AQ16: 10 | AR16: 2 | AS16: 0 | AT16: 6 | AU16: 6 | AV16: 1 | AW16: 0 | AX16: 1 | AY16: 0 | AZ16: 5 | BA16: 0 | BB16: 0 | BC16: 5 | BD16: 0 | BE16: 3 | BF16: 0 | BG16: 1 | BH16: 0 | BI16: 0 | BJ16: ==AI16 -> 12 | BK16: ==BJ16/N16 -> 4.8 | BL16: ==AL16/AI16 -> 0.66666667 | BM16: ==IF(BJ16=0,0,AM16/BJ16) -> 0 | BN16: ==IF(BJ16=0,0,AN16/BJ16) -> 0.5 | BO16: ==IF(BJ16=0,0,AO16/BJ16) -> 0.25 | BP16: ==IF(BJ16=0,0,AP16/BJ16) -> 0.25 | BQ16: ==-IF(BM16=0,0,BM16*LN(BM16))-IF(BN16=0,0,BN16*LN(BN16))-IF(BO16=0,0,BO16*LN(BO16))-IF(BP16=0,0,BP16*LN(BP16)) -> 1.0397208 | BR16: ==IF(BJ16=0,0,BQ16/LN(4)*100) -> 75 | BS16: ==_xlfn.XLOOKUP(B16,点位均值!$A:$A,点位均值!$B:$B,"无匹配") -> 2.1655707 | BT16: ==_xlfn.XLOOKUP(B16,点位均值!$A:$A,点位均值!$C:$C,"无匹配") -> 1.7607702
A17: 2 | B17: 上海市徐汇区湖南路街道安福路166号 | C17: A2 商业界面 | D17: B1a 无后退 | E17: B2b 橱窗 | F17: B3a-ii 外摆在外侧 | G17: B3b-ii 招牌；B3b-iii 大雨棚 | I17: C3 建筑尺度（整栋建筑） | J17: D2 行道树；D3 花坛 | K17: ==IF(TRIM(CLEAN(J17))="","",(IF(ISNUMBER(SEARCH("公共座椅",TRIM(CLEAN(J17)))),2,0)+IF(ISNUMBER(SEARCH("行道树",TRIM(CLEAN(J17)))),1,0)+IF(ISNUMBER(SEARCH("花坛",TRIM(CLEAN(J17)))),0.75,0)+IF(ISNUMBER(SEARCH("电线杆",TRIM(CLEAN(J17)))),0.4,0)+IF(ISNUMBER(SEARCH("路灯",TRIM(CLEAN(J17)))),0.45,0)+IF(ISNUMBER(SEARCH("共享单车",TRIM(CLEAN(J17)))),0.35,0)+IF(ISNUMBER(SEARCH("垃圾桶",TRIM(CLEAN(J17)))),-0.5,0))/(1+LN(1+(LEN(TRIM(CLEAN(J17)))-LEN(SUBSTITUTE(TRIM(CLEAN(J17)),";",""))+1)))) -> 1.0335782 | L17: 20 | M17: 5 | N17: 100 | O17: 餐饮/饮品 | P17: 1 | Q17: 4 | R17: 120 | S17: 80 | T17: 50 | U17: 5 | V17: 5 | W17: 4 | X17: 界面连续性好 | Y17: 164.jpg | Z17: 5 | AA17: 2 | AB17: 4 | AC17: 餐厅门口有围合 | AD17: 164.jpg | AE17: 树木；建筑；雨棚 | AF17: 70 | AG17: 4 | AH17: 5 | AI17: 5 | AJ17: 2 | AK17: 1 | AL17: 4 | AM17: 0 | AN17: 4 | AO17: 1 | AP17: 0 | AQ17: 2 | AR17: 3 | AS17: 0 | AT17: 5 | AU17: 0 | AV17: 3 | AW17: 2 | AX17: 0 | AY17: 2 | AZ17: 0 | BA17: 0 | BB17: 0 | BC17: 3 | BD17: 0 | BE17: 0 | BF17: 0 | BG17: 0 | BH17: 0 | BI17: 0 | BJ17: ==AI17 -> 5 | BK17: ==BJ17/N17 -> 0.05 | BL17: ==AL17/AI17 -> 0.8 | BM17: ==IF(BJ17=0,0,AM17/BJ17) -> 0 | BN17: ==IF(BJ17=0,0,AN17/BJ17) -> 0.8 | BO17: ==IF(BJ17=0,0,AO17/BJ17) -> 0.2 | BP17: ==IF(BJ17=0,0,AP17/BJ17) -> 0 | BQ17: ==-IF(BM17=0,0,BM17*LN(BM17))-IF(BN17=0,0,BN17*LN(BN17))-IF(BO17=0,0,BO17*LN(BO17))-IF(BP17=0,0,BP17*LN(BP17)) -> 0.50040242 | BR17: ==IF(BJ17=0,0,BQ17/LN(4)*100) -> 36.096405 | BS17: ==_xlfn.XLOOKUP(B17,点位均值!$A:$A,点位均值!$B:$B,"无匹配") -> 0.88610422 | BT17: ==_xlfn.XLOOKUP(B17,点位均值!$A:$A,点位均值!$C:$C,"无匹配") -> 5.2955614
A18: 6 | B18: 上海市徐汇区湖南路街道安福路290号 | C18: A3 公共机构界面 | D18: B1d 整体后退 | E18: B2d 完全开敞 | G18: B3b-iii 大雨棚 | I18: C3 建筑尺度（整栋建筑） | J18: D2 行道树；D3 花坛 | K18: ==IF(TRIM(CLEAN(J18))="","",(IF(ISNUMBER(SEARCH("公共座椅",TRIM(CLEAN(J18)))),2,0)+IF(ISNUMBER(SEARCH("行道树",TRIM(CLEAN(J18)))),1,0)+IF(ISNUMBER(SEARCH("花坛",TRIM(CLEAN(J18)))),0.75,0)+IF(ISNUMBER(SEARCH("电线杆",TRIM(CLEAN(J18)))),0.4,0)+IF(ISNUMBER(SEARCH("路灯",TRIM(CLEAN(J18)))),0.45,0)+IF(ISNUMBER(SEARCH("共享单车",TRIM(CLEAN(J18)))),0.35,0)+IF(ISNUMBER(SEARCH("垃圾桶",TRIM(CLEAN(J18)))),-0.5,0))/(1+LN(1+(LEN(TRIM(CLEAN(J18)))-LEN(SUBSTITUTE(TRIM(CLEAN(J18)),";",""))+1)))) -> 1.0335782 | L18: 50 | M18: 5 | N18: 100 | O18: 文化展示 | P18: 1 | Q18: 4 | U18: 4 | V18: 4 | W18: 3 | Z18: 2 | AA18: 4 | AB18: 5 | AE18: 树木；雨棚 | AF18: 80 | AG18: 4 | AH18: 3 | AI18: 11 | AJ18: 4 | AK18: 2 | AL18: 9 | AM18: 0 | AN18: 11 | AO18: 0 | AP18: 0 | AQ18: 4 | AR18: 7 | AS18: 0 | AT18: 9 | AU18: 2 | AV18: 3 | AW18: 0 | AX18: 0 | AY18: 0 | AZ18: 1 | BA18: 0 | BB18: 0 | BC18: 11 | BD18: 0 | BE18: 0 | BF18: 0 | BG18: 0 | BH18: 1 | BI18: 0 | BJ18: ==AI18 -> 11 | BK18: ==BJ18/N18 -> 0.11 | BL18: ==AL18/AI18 -> 0.81818182 | BM18: ==IF(BJ18=0,0,AM18/BJ18) -> 0 | BN18: ==IF(BJ18=0,0,AN18/BJ18) -> 1 | BO18: ==IF(BJ18=0,0,AO18/BJ18) -> 0 | BP18: ==IF(BJ18=0,0,AP18/BJ18) -> 0 | BQ18: ==-IF(BM18=0,0,BM18*LN(BM18))-IF(BN18=0,0,BN18*LN(BN18))-IF(BO18=0,0,BO18*LN(BO18))-IF(BP18=0,0,BP18*LN(BP18)) -> 0 | BR18: ==IF(BJ18=0,0,BQ18/LN(4)*100) -> 0 | BS18: ==_xlfn.XLOOKUP(B18,点位均值!$A:$A,点位均值!$B:$B,"无匹配") -> 0.75210918 | BT18: ==_xlfn.XLOOKUP(B18,点位均值!$A:$A,点位均值!$C:$C,"无匹配") -> 3.1383812
A19: 68 | B19: 上海市静安区南京西路街道巨鹿路845弄10号 | C19: A2 商业界面 | D19: B1b 区域后退 | E19: B2d 完全开敞 | I19: C2 开间尺度（单个店面或小片连续界面） | J19: D2 行道树；D4 电线杆；D6 共享单车 | K19: ==IF(TRIM(CLEAN(J19))="","",(IF(ISNUMBER(SEARCH("公共座椅",TRIM(CLEAN(J19)))),2,0)+IF(ISNUMBER(SEARCH("行道树",TRIM(CLEAN(J19)))),1,0)+IF(ISNUMBER(SEARCH("花坛",TRIM(CLEAN(J19)))),0.75,0)+IF(ISNUMBER(SEARCH("电线杆",TRIM(CLEAN(J19)))),0.4,0)+IF(ISNUMBER(SEARCH("路灯",TRIM(CLEAN(J19)))),0.45,0)+IF(ISNUMBER(SEARCH("共享单车",TRIM(CLEAN(J19)))),0.35,0)+IF(ISNUMBER(SEARCH("垃圾桶",TRIM(CLEAN(J19)))),-0.5,0))/(1+LN(1+(LEN(TRIM(CLEAN(J19)))-LEN(SUBSTITUTE(TRIM(CLEAN(J19)),";",""))+1)))) -> 1.0335782 | L19: 16.35 | M19: 1 | N19: 51.2 | O19: 零售；生活服务 | P19: 2 | Q19: 4 | R19: 15783 | S19: 0 | T19: 0 | U19: 4 | V19: 3 | W19: 4 | X19: 界面连续，均为店铺 | Y19: 736.jpg | Z19: 4 | AA19: 4 | AB19: 3 | AC19: 无座椅停留，但入口空间退让抬升可供站立停留 | AD19: 736.jpg | AE19: 树木；建筑 | AF19: 80 | AG19: 3 | AH19: 4 | AI19: 3 | AJ19: 1 | AK19: 0 | AL19: 3 | AM19: 0 | AN19: 3 | AO19: 0 | AP19: 0 | AQ19: 1 | AR19: 2 | AS19: 0 | AT19: 0 | AU19: 3 | AV19: 0 | AW19: 0 | AX19: 0 | AY19: 3 | AZ19: 0 | BA19: 0 | BB19: 0 | BC19: 0 | BD19: 0 | BE19: 0 | BF19: 0 | BG19: 0 | BH19: 0 | BI19: 0 | BJ19: ==AI19 -> 3 | BK19: ==BJ19/N19 -> 0.05859375 | BL19: ==AL19/AI19 -> 1 | BM19: ==IF(BJ19=0,0,AM19/BJ19) -> 0 | BN19: ==IF(BJ19=0,0,AN19/BJ19) -> 1 | BO19: ==IF(BJ19=0,0,AO19/BJ19) -> 0 | BP19: ==IF(BJ19=0,0,AP19/BJ19) -> 0 | BQ19: ==-IF(BM19=0,0,BM19*LN(BM19))-IF(BN19=0,0,BN19*LN(BN19))-IF(BO19=0,0,BO19*LN(BO19))-IF(BP19=0,0,BP19*LN(BP19)) -> 0 | BR19: ==IF(BJ19=0,0,BQ19/LN(4)*100) -> 0 | BS19: ==_xlfn.XLOOKUP(B19,点位均值!$A:$A,点位均值!$B:$B,"无匹配") -> 0.1 | BT19: ==_xlfn.XLOOKUP(B19,点位均值!$A:$A,点位均值!$C:$C,"无匹配") -> 4.0031332
A20: 125 | B20: 上海市徐汇区天平路街道襄阳南路414号 | C20: A2 商业界面 | D20: B1d 整体后退 | E20: B2b 橱窗 | F20: B3a-ii 外摆在外侧 | I20: C3 建筑尺度（整栋建筑） | J20: D2 行道树；D3 花坛 | K20: ==IF(TRIM(CLEAN(J20))="","",(IF(ISNUMBER(SEARCH("公共座椅",TRIM(CLEAN(J20)))),2,0)+IF(ISNUMBER(SEARCH("行道树",TRIM(CLEAN(J20)))),1,0)+IF(ISNUMBER(SEARCH("花坛",TRIM(CLEAN(J20)))),0.75,0)+IF(ISNUMBER(SEARCH("电线杆",TRIM(CLEAN(J20)))),0.4,0)+IF(ISNUMBER(SEARCH("路灯",TRIM(CLEAN(J20)))),0.45,0)+IF(ISNUMBER(SEARCH("共享单车",TRIM(CLEAN(J20)))),0.35,0)+IF(ISNUMBER(SEARCH("垃圾桶",TRIM(CLEAN(J20)))),-0.5,0))/(1+LN(1+(LEN(TRIM(CLEAN(J20)))-LEN(SUBSTITUTE(TRIM(CLEAN(J20)),";",""))+1)))) -> 1.0335782 | L20: 10 | M20: 0 | N20: 5 | O20: 餐饮/饮品 | P20: 1 | Q20: 5 | R20: 115 | S20: 100 | T20: 8 | U20: 3.75 | V20: 3 | W20: 3.25 | X20: 独立独栋建筑 | Z20: 3.25 | AA20: 3.75 | AB20: 4.25 | AC20: 一级踏步抬升 | AE20: 树木 | AF20: 50 | AG20: 3.5 | AH20: 3.25 | AI20: 1 | AJ20: 0 | AK20: 1 | AL20: 0 | AM20: 0 | AN20: 1 | AO20: 0 | AP20: 0 | AQ20: 1 | AR20: 0 | AS20: 0 | AT20: 1 | AU20: 0 | AV20: 0 | AW20: 0 | AX20: 0 | AY20: 0 | AZ20: 0 | BA20: 0 | BB20: 0 | BC20: 1 | BD20: 0 | BE20: 0 | BF20: 0 | BG20: 0 | BH20: 0 | BI20: 0 | BJ20: ==AI20 -> 1 | BK20: ==BJ20/N20 -> 0.2 | BL20: ==AL20/AI20 -> 0 | BM20: ==IF(BJ20=0,0,AM20/BJ20) -> 0 | BN20: ==IF(BJ20=0,0,AN20/BJ20) -> 1 | BO20: ==IF(BJ20=0,0,AO20/BJ20) -> 0 | BP20: ==IF(BJ20=0,0,AP20/BJ20) -> 0 | BQ20: ==-IF(BM20=0,0,BM20*LN(BM20))-IF(BN20=0,0,BN20*LN(BN20))-IF(BO20=0,0,BO20*LN(BO20))-IF(BP20=0,0,BP20*LN(BP20)) -> 0 | BR20: ==IF(BJ20=0,0,BQ20/LN(4)*100) -> 0 | BS20: ==_xlfn.XLOOKUP(B20,点位均值!$A:$A,点位均值!$B:$B,"无匹配") -> 0.54218362 | BT20: ==_xlfn.XLOOKUP(B20,点位均值!$A:$A,点位均值!$C:$C,"无匹配") -> 2.1420366
A21: 93 | B21: 上海市徐汇区天平路街道建国西路320号 | C21: A2 商业界面 | D21: B1a 无后退 | E21: B2b 橱窗 | F21: B3b-iii 大雨棚 | I21: C2 开间尺度（单个店面或小片连续界面） | J21: D2 行道树；D6 共享单车 | K21: ==IF(TRIM(CLEAN(J21))="","",(IF(ISNUMBER(SEARCH("公共座椅",TRIM(CLEAN(J21)))),2,0)+IF(ISNUMBER(SEARCH("行道树",TRIM(CLEAN(J21)))),1,0)+IF(ISNUMBER(SEARCH("花坛",TRIM(CLEAN(J21)))),0.75,0)+IF(ISNUMBER(SEARCH("电线杆",TRIM(CLEAN(J21)))),0.5,0)+IF(ISNUMBER(SEARCH("路灯",TRIM(CLEAN(J21)))),0.5,0)+IF(ISNUMBER(SEARCH("共享单车",TRIM(CLEAN(J21)))),0.5,0)+IF(ISNUMBER(SEARCH("垃圾桶",TRIM(CLEAN(J21)))),-0.5,0))/(1+LN(1+(LEN(TRIM(CLEAN(J21)))-LEN(SUBSTITUTE(TRIM(CLEAN(J21)),";",""))+1)))) -> 0.88592416 | L21: 11 | M21: 1.5 | N21: 17 | O21: 居住 | P21: 1 | Q21: 3 | R21: 0 | S21: 10 | T21: 3 | U21: 4 | V21: 4 | W21: 3 | X21: 沿街商铺立面大体连贯，大面积玻璃窗形成通透界面，零星的店门、设备箱体轻微打断界面完整性 | Z21: 3 | AA21: 3 | AB21: 4 | AC21: 人行道无明显高差，商铺橱窗与外摆形成半开放停留空间，快速通行、逛街闲逛、短时休憩的人群混合出现 | AE21: 树木 | AF21: 60 | AG21: 4 | AH21: 3 | BJ21: ==AI21 -> 0 | BK21: ==BJ21/N21 -> 0 | BL21: ==AL21/AI21 -> #DIV/0! | BM21: ==IF(BJ21=0,0,AM21/BJ21) -> 0 | BN21: ==IF(BJ21=0,0,AN21/BJ21) -> 0 | BO21: ==IF(BJ21=0,0,AO21/BJ21) -> 0 | BP21: ==IF(BJ21=0,0,AP21/BJ21) -> 0 | BQ21: ==-IF(BM21=0,0,BM21*LN(BM21))-IF(BN21=0,0,BN21*LN(BN21))-IF(BO21=0,0,BO21*LN(BO21))-IF(BP21=0,0,BP21*LN(BP21)) -> 0 | BR21: ==IF(BJ21=0,0,BQ21/LN(4)*100) -> 0 | BS21: ==_xlfn.XLOOKUP(B21,点位均值!$A:$A,点位均值!$B:$B,"无匹配") -> 无匹配 | BT21: ==_xlfn.XLOOKUP(B21,点位均值!$A:$A,点位均值!$C:$C,"无匹配") -> 无匹配
A22: 94 | B22: 上海市徐汇区天平路街道建国西路338号 | C22: A2 商业界面 | D22: B1c 局部后退 | E22: B2d 完全开敞 | F22: B3a-i 外摆在内侧 | I22: C2 开间尺度（单个店面或小片连续界面） | J22: D2 行道树；D6 共享单车 | K22: ==IF(TRIM(CLEAN(J22))="","",(IF(ISNUMBER(SEARCH("公共座椅",TRIM(CLEAN(J22)))),2,0)+IF(ISNUMBER(SEARCH("行道树",TRIM(CLEAN(J22)))),1,0)+IF(ISNUMBER(SEARCH("花坛",TRIM(CLEAN(J22)))),0.75,0)+IF(ISNUMBER(SEARCH("电线杆",TRIM(CLEAN(J22)))),0.5,0)+IF(ISNUMBER(SEARCH("路灯",TRIM(CLEAN(J22)))),0.5,0)+IF(ISNUMBER(SEARCH("共享单车",TRIM(CLEAN(J22)))),0.5,0)+IF(ISNUMBER(SEARCH("垃圾桶",TRIM(CLEAN(J22)))),-0.5,0))/(1+LN(1+(LEN(TRIM(CLEAN(J22)))-LEN(SUBSTITUTE(TRIM(CLEAN(J22)),";",""))+1)))) -> 0.88592416 | L22: 15 | M22: 1.3 | N22: 22 | O22: 餐饮/饮品 | P22: 1 | Q22: 4 | R22: 78 | S22: 70 | T22: 9 | U22: 5 | V22: 4 | W22: 4 | X22: 连续性很好 | Z22: 4 | AA22: 4 | AB22: 4 | AC22: 无特殊处理 | AE22: 树木；雨棚 | AF22: 70 | AG22: 3 | AH22: 4 | AI22: 2 | AJ22: 0 | AK22: 2 | AL22: 0 | AM22: 0 | AN22: 1 | AO22: 1 | AP22: 0 | AQ22: 2 | AR22: 0 | AS22: 0 | AT22: 0 | AU22: 2 | AV22: 0 | AW22: 1 | AX22: 0 | AY22: 0 | AZ22: 0 | BA22: 0 | BB22: 0 | BC22: 1 | BD22: 0 | BE22: 0 | BF22: 0 | BG22: 0 | BH22: 0 | BI22: 0 | BJ22: ==AI22 -> 2 | BK22: ==BJ22/N22 -> 0.090909091 | BL22: ==AL22/AI22 -> 0 | BM22: ==IF(BJ22=0,0,AM22/BJ22) -> 0 | BN22: ==IF(BJ22=0,0,AN22/BJ22) -> 0.5 | BO22: ==IF(BJ22=0,0,AO22/BJ22) -> 0.5 | BP22: ==IF(BJ22=0,0,AP22/BJ22) -> 0 | BQ22: ==-IF(BM22=0,0,BM22*LN(BM22))-IF(BN22=0,0,BN22*LN(BN22))-IF(BO22=0,0,BO22*LN(BO22))-IF(BP22=0,0,BP22*LN(BP22)) -> 0.69314718 | BR22: ==IF(BJ22=0,0,BQ22/LN(4)*100) -> 50 | BS22: ==_xlfn.XLOOKUP(B22,点位均值!$A:$A,点位均值!$B:$B,"无匹配") -> 0.91066998 | BT22: ==_xlfn.XLOOKUP(B22,点位均值!$A:$A,点位均值!$C:$C,"无匹配") -> 1.7543081
A23: 66 | B23: 上海市静安区南京西路街道巨鹿路754号 | C23: A2 商业界面 | D23: B1d 整体后退 | E23: B2d 完全开敞 | F23: B3a-i 外摆在内侧 | I23: C3 建筑尺度（整栋建筑） | J23: D2 行道树；D5 路灯 | K23: ==IF(TRIM(CLEAN(J23))="","",(IF(ISNUMBER(SEARCH("公共座椅",TRIM(CLEAN(J23)))),2,0)+IF(ISNUMBER(SEARCH("行道树",TRIM(CLEAN(J23)))),1,0)+IF(ISNUMBER(SEARCH("花坛",TRIM(CLEAN(J23)))),0.75,0)+IF(ISNUMBER(SEARCH("电线杆",TRIM(CLEAN(J23)))),0.4,0)+IF(ISNUMBER(SEARCH("路灯",TRIM(CLEAN(J23)))),0.45,0)+IF(ISNUMBER(SEARCH("共享单车",TRIM(CLEAN(J23)))),0.35,0)+IF(ISNUMBER(SEARCH("垃圾桶",TRIM(CLEAN(J23)))),-0.5,0))/(1+LN(1+(LEN(TRIM(CLEAN(J23)))-LEN(SUBSTITUTE(TRIM(CLEAN(J23)),";",""))+1)))) -> 0.85639336 | L23: 20.6 | M23: 2.5 | N23: 63.5 | O23: 餐饮/饮品 | P23: 2 | Q23: 5 | R23: 60 | S23: 100 | T23: 25 | U23: 4 | V23: 2 | W23: 2 | X23: 界面较为连续，左侧商店门口开洞退让 | Y23: 737.jpg | Z23: 3 | AA23: 4 | AB23: 4 | AC23: 部分座椅设施在建筑退让内部，有抬升，其余街边座椅设施不存在特殊铺地、抬升、围合 | AD23: 737.jpg | AE23: 树木；雨棚 | AF23: 90 | AG23: 3 | AH23: 3 | AI23: 17 | AJ23: 7 | AK23: 2 | AL23: 15 | AM23: 1 | AN23: 15 | AO23: 1 | AP23: 0 | AQ23: 8 | AR23: 9 | AS23: 0 | AT23: 15 | AU23: 2 | AV23: 0 | AW23: 0 | AX23: 5 | AY23: 0 | AZ23: 11 | BA23: 0 | BB23: 14 | BC23: 4 | BD23: 0 | BE23: 0 | BF23: 0 | BG23: 0 | BH23: 0 | BI23: 0 | BJ23: ==AI23 -> 17 | BK23: ==BJ23/N23 -> 0.26771654 | BL23: ==AL23/AI23 -> 0.88235294 | BM23: ==IF(BJ23=0,0,AM23/BJ23) -> 0.058823529 | BN23: ==IF(BJ23=0,0,AN23/BJ23) -> 0.88235294 | BO23: ==IF(BJ23=0,0,AO23/BJ23) -> 0.058823529 | BP23: ==IF(BJ23=0,0,AP23/BJ23) -> 0 | BQ23: ==-IF(BM23=0,0,BM23*LN(BM23))-IF(BN23=0,0,BN23*LN(BN23))-IF(BO23=0,0,BO23*LN(BO23))-IF(BP23=0,0,BP23*LN(BP23)) -> 0.44375728 | BR23: ==IF(BJ23=0,0,BQ23/LN(4)*100) -> 32.010322 | BS23: ==_xlfn.XLOOKUP(B23,点位均值!$A:$A,点位均值!$B:$B,"无匹配") -> 1.3138374 | BT23: ==_xlfn.XLOOKUP(B23,点位均值!$A:$A,点位均值!$C:$C,"无匹配") -> 3.6838274
A24: 69 | B24: 上海市静安区南京西路街道襄阳北路5号 | C24: A2 商业界面 | D24: B1c 局部后退 | E24: B2c 墙面开洞 | I24: C2 开间尺度（单个店面或小片连续界面） | J24: D2 行道树；D5 路灯 | K24: ==IF(TRIM(CLEAN(J24))="","",(IF(ISNUMBER(SEARCH("公共座椅",TRIM(CLEAN(J24)))),2,0)+IF(ISNUMBER(SEARCH("行道树",TRIM(CLEAN(J24)))),1,0)+IF(ISNUMBER(SEARCH("花坛",TRIM(CLEAN(J24)))),0.75,0)+IF(ISNUMBER(SEARCH("电线杆",TRIM(CLEAN(J24)))),0.4,0)+IF(ISNUMBER(SEARCH("路灯",TRIM(CLEAN(J24)))),0.45,0)+IF(ISNUMBER(SEARCH("共享单车",TRIM(CLEAN(J24)))),0.35,0)+IF(ISNUMBER(SEARCH("垃圾桶",TRIM(CLEAN(J24)))),-0.5,0))/(1+LN(1+(LEN(TRIM(CLEAN(J24)))-LEN(SUBSTITUTE(TRIM(CLEAN(J24)),";",""))+1)))) -> 0.85639336 | O24: 餐饮/饮品 | P24: 3 | Q24: 1 | R24: 89 | S24: 0 | T24: 8 | U24: 3 | V24: 2 | W24: 2 | Y24: IMG_5529.jpg | Z24: 5 | AA24: 1 | AB24: 4 | AD24: IMG_5529.jpg | AE24: 树木；建筑 | AF24: 50 | AG24: 4 | AH24: 4 | AI24: 2 | AJ24: 2 | AK24: 0 | AL24: 2 | AM24: 0 | AN24: 0 | AO24: 2 | AP24: 0 | AQ24: 2 | AR24: 0 | AS24: 0 | AT24: 2 | AU24: 0 | AV24: 0 | AW24: 0 | AX24: 0 | AY24: 0 | AZ24: 2 | BA24: 0 | BB24: 0 | BC24: 2 | BD24: 0 | BE24: 0 | BF24: 0 | BG24: 0 | BH24: 0 | BI24: 0 | BJ24: ==AI24 -> 2 | BK24: ==BJ24/N24 -> #DIV/0! | BL24: ==AL24/AI24 -> 1 | BM24: ==IF(BJ24=0,0,AM24/BJ24) -> 0 | BN24: ==IF(BJ24=0,0,AN24/BJ24) -> 0 | BO24: ==IF(BJ24=0,0,AO24/BJ24) -> 1 | BP24: ==IF(BJ24=0,0,AP24/BJ24) -> 0 | BQ24: ==-IF(BM24=0,0,BM24*LN(BM24))-IF(BN24=0,0,BN24*LN(BN24))-IF(BO24=0,0,BO24*LN(BO24))-IF(BP24=0,0,BP24*LN(BP24)) -> 0 | BR24: ==IF(BJ24=0,0,BQ24/LN(4)*100) -> 0 | BS24: ==_xlfn.XLOOKUP(B24,点位均值!$A:$A,点位均值!$B:$B,"无匹配") -> 3.2444169 | BT24: ==_xlfn.XLOOKUP(B24,点位均值!$A:$A,点位均值!$C:$C,"无匹配") -> 1.8835509
A25: 74 | B25: 上海市黄浦区瑞金二路街道南昌路354号 | C25: A2 商业界面 | D25: B1d 整体后退 | E25: B2b 橱窗 | G25: B3c 围栏 | I25: C2 开间尺度（单个店面或小片连续界面） | J25: D2 行道树；D5 路灯 | K25: ==IF(TRIM(CLEAN(J25))="","",(IF(ISNUMBER(SEARCH("公共座椅",TRIM(CLEAN(J25)))),2,0)+IF(ISNUMBER(SEARCH("行道树",TRIM(CLEAN(J25)))),1,0)+IF(ISNUMBER(SEARCH("花坛",TRIM(CLEAN(J25)))),0.75,0)+IF(ISNUMBER(SEARCH("电线杆",TRIM(CLEAN(J25)))),0.4,0)+IF(ISNUMBER(SEARCH("路灯",TRIM(CLEAN(J25)))),0.45,0)+IF(ISNUMBER(SEARCH("共享单车",TRIM(CLEAN(J25)))),0.35,0)+IF(ISNUMBER(SEARCH("垃圾桶",TRIM(CLEAN(J25)))),-0.5,0))/(1+LN(1+(LEN(TRIM(CLEAN(J25)))-LEN(SUBSTITUTE(TRIM(CLEAN(J25)),";",""))+1)))) -> 0.85639336 | L25: 7 | M25: 2 | N25: 15 | O25: 零售 | P25: 2 | Q25: 3 | R25: 2500 | S25: 70 | T25: 10 | U25: 5 | V25: 1 | W25: 4 | X25: 退界形成小庭院，不连续 | Z25: 5 | AA25: 5 | AB25: 5 | AC25: 三级台阶上行进入店铺 | AE25: 树木；建筑 | AF25: 60 | AG25: 5 | AH25: 5 | AI25: 4 | AJ25: 2 | AK25: 0 | AL25: 4 | AM25: 0 | AN25: 4 | AO25: 0 | AP25: 0 | AQ25: 4 | AR25: 0 | AS25: 0 | AT25: 0 | AU25: 4 | AV25: 0 | AW25: 0 | AX25: 0 | AY25: 0 | AZ25: 4 | BA25: 0 | BB25: 0 | BC25: 0 | BD25: 0 | BE25: 0 | BF25: 0 | BG25: 0 | BH25: 0 | BI25: 0 | BJ25: ==AI25 -> 4 | BK25: ==BJ25/N25 -> 0.26666667 | BL25: ==AL25/AI25 -> 1 | BM25: ==IF(BJ25=0,0,AM25/BJ25) -> 0 | BN25: ==IF(BJ25=0,0,AN25/BJ25) -> 1 | BO25: ==IF(BJ25=0,0,AO25/BJ25) -> 0 | BP25: ==IF(BJ25=0,0,AP25/BJ25) -> 0 | BQ25: ==-IF(BM25=0,0,BM25*LN(BM25))-IF(BN25=0,0,BN25*LN(BN25))-IF(BO25=0,0,BO25*LN(BO25))-IF(BP25=0,0,BP25*LN(BP25)) -> 0 | BR25: ==IF(BJ25=0,0,BQ25/LN(4)*100) -> 0 | BS25: ==_xlfn.XLOOKUP(B25,点位均值!$A:$A,点位均值!$B:$B,"无匹配") -> 0.8369727 | BT25: ==_xlfn.XLOOKUP(B25,点位均值!$A:$A,点位均值!$C:$C,"无匹配") -> 0.90130548
A26: 77 | B26: 上海市黄浦区瑞金二路街道永嘉路120号 | C26: A2 商业界面 | D26: B1a 无后退 | E26: B2b 橱窗 | F26: B3a-i 外摆在内侧 | I26: C2 开间尺度（单个店面或小片连续界面） | J26: D2 行道树；D5 路灯 | K26: ==IF(TRIM(CLEAN(J26))="","",(IF(ISNUMBER(SEARCH("公共座椅",TRIM(CLEAN(J26)))),2,0)+IF(ISNUMBER(SEARCH("行道树",TRIM(CLEAN(J26)))),1,0)+IF(ISNUMBER(SEARCH("花坛",TRIM(CLEAN(J26)))),0.75,0)+IF(ISNUMBER(SEARCH("电线杆",TRIM(CLEAN(J26)))),0.4,0)+IF(ISNUMBER(SEARCH("路灯",TRIM(CLEAN(J26)))),0.45,0)+IF(ISNUMBER(SEARCH("共享单车",TRIM(CLEAN(J26)))),0.35,0)+IF(ISNUMBER(SEARCH("垃圾桶",TRIM(CLEAN(J26)))),-0.5,0))/(1+LN(1+(LEN(TRIM(CLEAN(J26)))-LEN(SUBSTITUTE(TRIM(CLEAN(J26)),";",""))+1)))) -> 0.85639336 | L26: 3.5 | M26: 0 | N26: 5 | O26: 餐饮/饮品 | P26: 1 | Q26: 3 | R26: 5 | S26: 80 | T26: 5 | U26: 3 | V26: 2 | W26: 1 | Z26: 1 | AA26: 2 | AB26: 3 | AE26: 树木；建筑 | AF26: 70 | AG26: 2 | AH26: 2 | AI26: 7 | AJ26: 3 | AK26: 1 | AL26: 6 | AM26: 1 | AN26: 0 | AO26: 3 | AP26: 3 | AQ26: 3 | AR26: 4 | AS26: 0 | AT26: 0 | AU26: 7 | AV26: 4 | AW26: 3 | AX26: 0 | AY26: 0 | AZ26: 0 | BA26: 0 | BB26: 0 | BC26: 0 | BD26: 0 | BE26: 0 | BF26: 0 | BG26: 0 | BH26: 0 | BI26: 0 | BJ26: ==AI26 -> 7 | BK26: ==BJ26/N26 -> 1.4 | BL26: ==AL26/AI26 -> 0.85714286 | BM26: ==IF(BJ26=0,0,AM26/BJ26) -> 0.14285714 | BN26: ==IF(BJ26=0,0,AN26/BJ26) -> 0 | BO26: ==IF(BJ26=0,0,AO26/BJ26) -> 0.42857143 | BP26: ==IF(BJ26=0,0,AP26/BJ26) -> 0.42857143 | BQ26: ==-IF(BM26=0,0,BM26*LN(BM26))-IF(BN26=0,0,BN26*LN(BN26))-IF(BO26=0,0,BO26*LN(BO26))-IF(BP26=0,0,BP26*LN(BP26)) -> 1.0042425 | BR26: ==IF(BJ26=0,0,BQ26/LN(4)*100) -> 72.440782 | BS26: ==_xlfn.XLOOKUP(B26,点位均值!$A:$A,点位均值!$B:$B,"无匹配") -> 1.0966678 | BT26: ==_xlfn.XLOOKUP(B26,点位均值!$A:$A,点位均值!$C:$C,"无匹配") -> 1.3961209
A27: 98 | B27: 上海市徐汇区天平路街道陕西南路570号 | C27: A2 商业界面 | D27: B1a 无后退 | E27: B2d 完全开敞 | F27: B3a-i 外摆在内侧 | I27: C2 开间尺度（单个店面或小片连续界面） | J27: D2 行道树；D5 路灯 | K27: ==IF(TRIM(CLEAN(J27))="","",(IF(ISNUMBER(SEARCH("公共座椅",TRIM(CLEAN(J27)))),2,0)+IF(ISNUMBER(SEARCH("行道树",TRIM(CLEAN(J27)))),1,0)+IF(ISNUMBER(SEARCH("花坛",TRIM(CLEAN(J27)))),0.75,0)+IF(ISNUMBER(SEARCH("电线杆",TRIM(CLEAN(J27)))),0.4,0)+IF(ISNUMBER(SEARCH("路灯",TRIM(CLEAN(J27)))),0.45,0)+IF(ISNUMBER(SEARCH("共享单车",TRIM(CLEAN(J27)))),0.35,0)+IF(ISNUMBER(SEARCH("垃圾桶",TRIM(CLEAN(J27)))),-0.5,0))/(1+LN(1+(LEN(TRIM(CLEAN(J27)))-LEN(SUBSTITUTE(TRIM(CLEAN(J27)),";",""))+1)))) -> 0.85639336 | L27: 4 | M27: 0 | N27: 6 | O27: 零售 | P27: 2 | Q27: 2 | R27: 10 | S27: 70 | U27: 2 | V27: 4 | W27: 4 | X27: 均为生鲜、水产、菜场等生活性全开场店铺 | Z27: 1 | AA27: 1 | AB27: 3 | AE27: 树木；雨棚 | AF27: 80 | AG27: 3 | AH27: 3 | AI27: 4 | AJ27: 1 | AK27: 1 | AL27: 3 | AM27: 1 | AN27: 1 | AO27: 1 | AP27: 1 | AQ27: 2 | AR27: 1 | AS27: 1 | AT27: 1 | AU27: 3 | AV27: 3 | AW27: 0 | AX27: 0 | AY27: 0 | AZ27: 2 | BA27: 0 | BB27: 0 | BC27: 0 | BD27: 0 | BE27: 0 | BF27: 0 | BG27: 0 | BH27: 0 | BI27: 0 | BJ27: ==AI27 -> 4 | BK27: ==BJ27/N27 -> 0.66666667 | BL27: ==AL27/AI27 -> 0.75 | BM27: ==IF(BJ27=0,0,AM27/BJ27) -> 0.25 | BN27: ==IF(BJ27=0,0,AN27/BJ27) -> 0.25 | BO27: ==IF(BJ27=0,0,AO27/BJ27) -> 0.25 | BP27: ==IF(BJ27=0,0,AP27/BJ27) -> 0.25 | BQ27: ==-IF(BM27=0,0,BM27*LN(BM27))-IF(BN27=0,0,BN27*LN(BN27))-IF(BO27=0,0,BO27*LN(BO27))-IF(BP27=0,0,BP27*LN(BP27)) -> 1.3862944 | BR27: ==IF(BJ27=0,0,BQ27/LN(4)*100) -> 100 | BS27: ==_xlfn.XLOOKUP(B27,点位均值!$A:$A,点位均值!$B:$B,"无匹配") -> 1.3282878 | BT27: ==_xlfn.XLOOKUP(B27,点位均值!$A:$A,点位均值!$C:$C,"无匹配") -> 2.0644909
A28: 100 | B28: 上海市徐汇区天平路街道太原路45弄1号 | C28: A2 商业界面 | D28: B1d 整体后退 | E28: B2d 完全开敞 | H28: B3c 围栏 | I28: C4 组团尺度（院落或街区） | J28: D2 行道树；D5 路灯 | K28: ==IF(TRIM(CLEAN(J28))="","",(IF(ISNUMBER(SEARCH("公共座椅",TRIM(CLEAN(J28)))),2,0)+IF(ISNUMBER(SEARCH("行道树",TRIM(CLEAN(J28)))),1,0)+IF(ISNUMBER(SEARCH("花坛",TRIM(CLEAN(J28)))),0.75,0)+IF(ISNUMBER(SEARCH("电线杆",TRIM(CLEAN(J28)))),0.4,0)+IF(ISNUMBER(SEARCH("路灯",TRIM(CLEAN(J28)))),0.45,0)+IF(ISNUMBER(SEARCH("共享单车",TRIM(CLEAN(J28)))),0.35,0)+IF(ISNUMBER(SEARCH("垃圾桶",TRIM(CLEAN(J28)))),-0.5,0))/(1+LN(1+(LEN(TRIM(CLEAN(J28)))-LEN(SUBSTITUTE(TRIM(CLEAN(J28)),";",""))+1)))) -> 0.85639336 | L28: 28 | M28: 2 | N28: 20 | O28: 生活服务 | P28: 2 | Q28: 3 | R28: 36 | S28: 20 | T28: 9 | U28: 5 | V28: 4 | W28: 5 | X28: 临街界面完整连续，几乎无围墙、构筑物打断立面 | Z28: 5 | AA28: 5 | AB28: 5 | AC28: 临街有镜子，有围栏小院落 | AD28: 1788081895721.jpg | AE28: 树木 | AF28: 50 | AG28: 4 | AH28: 4 | AI28: 10 | AJ28: 4 | AK28: 1 | AL28: 9 | AM28: 0 | AN28: 7 | AO28: 2 | AP28: 1 | AQ28: 1 | AR28: 9 | AS28: 0 | AT28: 0 | AU28: 10 | AV28: 5 | AW28: 2 | AX28: 0 | AY28: 3 | AZ28: 2 | BA28: 0 | BB28: 0 | BC28: 0 | BD28: 0 | BE28: 0 | BF28: 0 | BG28: 0 | BH28: 0 | BI28: 0 | BJ28: ==AI28 -> 10 | BK28: ==BJ28/N28 -> 0.5 | BL28: ==AL28/AI28 -> 0.9 | BM28: ==IF(BJ28=0,0,AM28/BJ28) -> 0 | BN28: ==IF(BJ28=0,0,AN28/BJ28) -> 0.7 | BO28: ==IF(BJ28=0,0,AO28/BJ28) -> 0.2 | BP28: ==IF(BJ28=0,0,AP28/BJ28) -> 0.1 | BQ28: ==-IF(BM28=0,0,BM28*LN(BM28))-IF(BN28=0,0,BN28*LN(BN28))-IF(BO28=0,0,BO28*LN(BO28))-IF(BP28=0,0,BP28*LN(BP28)) -> 0.80181855 | BR28: ==IF(BJ28=0,0,BQ28/LN(4)*100) -> 57.838982 | BS28: ==_xlfn.XLOOKUP(B28,点位均值!$A:$A,点位均值!$B:$B,"无匹配") -> 0.54709677 | BT28: ==_xlfn.XLOOKUP(B28,点位均值!$A:$A,点位均值!$C:$C,"无匹配") -> 2.9485117
A29: 7 | B29: 上海市徐汇区湖南路街道东湖路30号 | C29: A2 商业界面 | D29: B1a 无后退 | E29: B2d 完全开敞 | H29: B3c 围栏 | I29: C3 建筑尺度（整栋建筑） | J29: D2 行道树；D4 电线杆 | K29: ==IF(TRIM(CLEAN(J29))="","",(IF(ISNUMBER(SEARCH("公共座椅",TRIM(CLEAN(J29)))),2,0)+IF(ISNUMBER(SEARCH("行道树",TRIM(CLEAN(J29)))),1,0)+IF(ISNUMBER(SEARCH("花坛",TRIM(CLEAN(J29)))),0.75,0)+IF(ISNUMBER(SEARCH("电线杆",TRIM(CLEAN(J29)))),0.4,0)+IF(ISNUMBER(SEARCH("路灯",TRIM(CLEAN(J29)))),0.45,0)+IF(ISNUMBER(SEARCH("共享单车",TRIM(CLEAN(J29)))),0.35,0)+IF(ISNUMBER(SEARCH("垃圾桶",TRIM(CLEAN(J29)))),-0.5,0))/(1+LN(1+(LEN(TRIM(CLEAN(J29)))-LEN(SUBSTITUTE(TRIM(CLEAN(J29)),";",""))+1)))) -> 0.82686255 | L29: 12 | M29: 0.5 | N29: 31.6 | O29: 餐饮/饮品 | P29: 1 | Q29: 2 | R29: 139 | S29: 30 | T29: 15 | U29: 5 | V29: 4 | W29: 3 | X29: 该餐饮店独立存在，一侧是小广场，一侧是内部通道大门，连续性不强 | Y29: IMG_20260830_142259.jpg | Z29: 4 | AA29: 4 | AB29: 5 | AC29: 警戒线围合一半座位。 | AE29: 树木 | AF29: 50 | AG29: 4 | AH29: 5 | AI29: 8 | AJ29: 3 | AK29: 2 | AL29: 6 | AM29: 0 | AN29: 4 | AO29: 4 | AP29: 0 | AQ29: 3 | AR29: 5 | AS29: 0 | AT29: 4 | AU29: 4 | AV29: 3 | AW29: 0 | AX29: 0 | AY29: 0 | AZ29: 2 | BA29: 0 | BB29: 0 | BC29: 5 | BD29: 0 | BE29: 0 | BF29: 0 | BG29: 0 | BH29: 0 | BI29: 0 | BJ29: ==AI29 -> 8 | BK29: ==BJ29/N29 -> 0.25316456 | BL29: ==AL29/AI29 -> 0.75 | BM29: ==IF(BJ29=0,0,AM29/BJ29) -> 0 | BN29: ==IF(BJ29=0,0,AN29/BJ29) -> 0.5 | BO29: ==IF(BJ29=0,0,AO29/BJ29) -> 0.5 | BP29: ==IF(BJ29=0,0,AP29/BJ29) -> 0 | BQ29: ==-IF(BM29=0,0,BM29*LN(BM29))-IF(BN29=0,0,BN29*LN(BN29))-IF(BO29=0,0,BO29*LN(BO29))-IF(BP29=0,0,BP29*LN(BP29)) -> 0.69314718 | BR29: ==IF(BJ29=0,0,BQ29/LN(4)*100) -> 50 | BS29: ==_xlfn.XLOOKUP(B29,点位均值!$A:$A,点位均值!$B:$B,"无匹配") -> 1.1808933 | BT29: ==_xlfn.XLOOKUP(B29,点位均值!$A:$A,点位均值!$C:$C,"无匹配") -> 2.2325065
A30: 15 | B30: 上海市徐汇区湖南路街道乌鲁木齐中路192号 | C30: A2 商业界面 | D30: B1a 无后退 | E30: B2b 橱窗 | F30: B3a-i 外摆在内侧 | G30: B3b-ii 招牌 | I30: C2 开间尺度（单个店面或小片连续界面） | J30: D2 行道树；D4 电线杆 | K30: ==IF(TRIM(CLEAN(J30))="","",(IF(ISNUMBER(SEARCH("公共座椅",TRIM(CLEAN(J30)))),2,0)+IF(ISNUMBER(SEARCH("行道树",TRIM(CLEAN(J30)))),1,0)+IF(ISNUMBER(SEARCH("花坛",TRIM(CLEAN(J30)))),0.75,0)+IF(ISNUMBER(SEARCH("电线杆",TRIM(CLEAN(J30)))),0.4,0)+IF(ISNUMBER(SEARCH("路灯",TRIM(CLEAN(J30)))),0.45,0)+IF(ISNUMBER(SEARCH("共享单车",TRIM(CLEAN(J30)))),0.35,0)+IF(ISNUMBER(SEARCH("垃圾桶",TRIM(CLEAN(J30)))),-0.5,0))/(1+LN(1+(LEN(TRIM(CLEAN(J30)))-LEN(SUBSTITUTE(TRIM(CLEAN(J30)),";",""))+1)))) -> 0.82686255 | L30: 4 | M30: 0 | N30: 0.5 | O30: 零售 | P30: 1 | Q30: 4 | R30: 177 | S30: 5 | T30: 2 | U30: 4 | V30: 4 | W30: 4 | X30: 界面连续性一般 | Y30: 194.jpg | Z30: 5 | AA30: 2 | AB30: 4 | AC30: 无明显属于商铺的停留处 | AD30: 194.jpg | AE30: 树木 | AF30: 15 | AG30: 4 | AH30: 3 | BJ30: ==AI30 -> 0 | BK30: ==BJ30/N30 -> 0 | BL30: ==AL30/AI30 -> #DIV/0! | BM30: ==IF(BJ30=0,0,AM30/BJ30) -> 0 | BN30: ==IF(BJ30=0,0,AN30/BJ30) -> 0 | BO30: ==IF(BJ30=0,0,AO30/BJ30) -> 0 | BP30: ==IF(BJ30=0,0,AP30/BJ30) -> 0 | BQ30: ==-IF(BM30=0,0,BM30*LN(BM30))-IF(BN30=0,0,BN30*LN(BN30))-IF(BO30=0,0,BO30*LN(BO30))-IF(BP30=0,0,BP30*LN(BP30)) -> 0 | BR30: ==IF(BJ30=0,0,BQ30/LN(4)*100) -> 0 | BS30: ==_xlfn.XLOOKUP(B30,点位均值!$A:$A,点位均值!$B:$B,"无匹配") -> 无匹配 | BT30: ==_xlfn.XLOOKUP(B30,点位均值!$A:$A,点位均值!$C:$C,"无匹配") -> 无匹配
A31: 17 | B31: 上海市徐汇区湖南路街道乌鲁木齐中路292号 | C31: A2 商业界面 | D31: B1a 无后退 | E31: B2b 橱窗 | G31: B3b-i 雨棚；B3b-ii 招牌 | I31: C2 开间尺度（单个店面或小片连续界面） | J31: D2 行道树；D4 电线杆 | K31: ==IF(TRIM(CLEAN(J31))="","",(IF(ISNUMBER(SEARCH("公共座椅",TRIM(CLEAN(J31)))),2,0)+IF(ISNUMBER(SEARCH("行道树",TRIM(CLEAN(J31)))),1,0)+IF(ISNUMBER(SEARCH("花坛",TRIM(CLEAN(J31)))),0.75,0)+IF(ISNUMBER(SEARCH("电线杆",TRIM(CLEAN(J31)))),0.4,0)+IF(ISNUMBER(SEARCH("路灯",TRIM(CLEAN(J31)))),0.45,0)+IF(ISNUMBER(SEARCH("共享单车",TRIM(CLEAN(J31)))),0.35,0)+IF(ISNUMBER(SEARCH("垃圾桶",TRIM(CLEAN(J31)))),-0.5,0))/(1+LN(1+(LEN(TRIM(CLEAN(J31)))-LEN(SUBSTITUTE(TRIM(CLEAN(J31)),";",""))+1)))) -> 0.82686255 | L31: 6 | M31: 0 | N31: 0.5 | O31: 餐饮/饮品 | P31: 1 | Q31: 4 | R31: 25 | S31: 10 | T31: 2 | U31: 5 | V31: 5 | W31: 5 | X31: 商铺入口处为通透的落地大玻璃 | Y31: 厕所.jpg | Z31: 5 | AA31: 3 | AB31: 4 | AC31: 商店没有无特殊铺地、抬升 | AD31: 厕所.jpg | AE31: 树木；雨棚 | AF31: 50 | AG31: 4 | AH31: 5 | AI31: 2 | AJ31: 1 | AK31: 0 | AL31: 2 | AM31: 0 | AN31: 2 | AO31: 0 | AP31: 0 | AQ31: 1 | AR31: 1 | AS31: 0 | AT31: 0 | AU31: 2 | AV31: 2 | AW31: 0 | AX31: 0 | AY31: 0 | AZ31: 0 | BA31: 0 | BB31: 0 | BC31: 2 | BD31: 0 | BE31: 0 | BF31: 0 | BG31: 0 | BH31: 0 | BI31: 0 | BJ31: ==AI31 -> 2 | BK31: ==BJ31/N31 -> 4 | BL31: ==AL31/AI31 -> 1 | BM31: ==IF(BJ31=0,0,AM31/BJ31) -> 0 | BN31: ==IF(BJ31=0,0,AN31/BJ31) -> 1 | BO31: ==IF(BJ31=0,0,AO31/BJ31) -> 0 | BP31: ==IF(BJ31=0,0,AP31/BJ31) -> 0 | BQ31: ==-IF(BM31=0,0,BM31*LN(BM31))-IF(BN31=0,0,BN31*LN(BN31))-IF(BO31=0,0,BO31*LN(BO31))-IF(BP31=0,0,BP31*LN(BP31)) -> 0 | BR31: ==IF(BJ31=0,0,BQ31/LN(4)*100) -> 0 | BS31: ==_xlfn.XLOOKUP(B31,点位均值!$A:$A,点位均值!$B:$B,"无匹配") -> 0.73870968 | BT31: ==_xlfn.XLOOKUP(B31,点位均值!$A:$A,点位均值!$C:$C,"无匹配") -> 5.4506527
A32: 24 | B32: 上海市徐汇区湖南路街道五原路58号 | C32: A2 商业界面 | D32: B1d 整体后退 | E32: B2b 橱窗 | F32: B3a-i 外摆在内侧 | I32: C3 建筑尺度（整栋建筑） | J32: D2 行道树；D4 电线杆 | K32: ==IF(TRIM(CLEAN(J32))="","",(IF(ISNUMBER(SEARCH("公共座椅",TRIM(CLEAN(J32)))),2,0)+IF(ISNUMBER(SEARCH("行道树",TRIM(CLEAN(J32)))),1,0)+IF(ISNUMBER(SEARCH("花坛",TRIM(CLEAN(J32)))),0.75,0)+IF(ISNUMBER(SEARCH("电线杆",TRIM(CLEAN(J32)))),0.4,0)+IF(ISNUMBER(SEARCH("路灯",TRIM(CLEAN(J32)))),0.45,0)+IF(ISNUMBER(SEARCH("共享单车",TRIM(CLEAN(J32)))),0.35,0)+IF(ISNUMBER(SEARCH("垃圾桶",TRIM(CLEAN(J32)))),-0.5,0))/(1+LN(1+(LEN(TRIM(CLEAN(J32)))-LEN(SUBSTITUTE(TRIM(CLEAN(J32)),";",""))+1)))) -> 0.82686255 | L32: 8 | M32: 1 | N32: 8 | O32: 餐饮/饮品 | P32: 1 | Q32: 5 | R32: 60 | S32: 90 | T32: 6 | U32: 5 | V32: 4 | W32: 4 | X32: 周围无连续节点 | Z32: 5 | AA32: 1 | AB32: 5 | AE32: 树木；雨棚 | AF32: 80 | AG32: 4 | AH32: 3 | AI32: 5 | AJ32: 2 | AK32: 0 | AL32: 5 | AM32: 0 | AN32: 3 | AO32: 2 | AP32: 0 | AQ32: 3 | AR32: 2 | AS32: 0 | AT32: 5 | AU32: 0 | AV32: 0 | AW32: 0 | AX32: 0 | AY32: 0 | AZ32: 5 | BA32: 0 | BB32: 5 | BC32: 1 | BD32: 0 | BE32: 0 | BF32: 0 | BG32: 0 | BH32: 0 | BI32: 0 | BJ32: ==AI32 -> 5 | BK32: ==BJ32/N32 -> 0.625 | BL32: ==AL32/AI32 -> 1 | BM32: ==IF(BJ32=0,0,AM32/BJ32) -> 0 | BN32: ==IF(BJ32=0,0,AN32/BJ32) -> 0.6 | BO32: ==IF(BJ32=0,0,AO32/BJ32) -> 0.4 | BP32: ==IF(BJ32=0,0,AP32/BJ32) -> 0 | BQ32: ==-IF(BM32=0,0,BM32*LN(BM32))-IF(BN32=0,0,BN32*LN(BN32))-IF(BO32=0,0,BO32*LN(BO32))-IF(BP32=0,0,BP32*LN(BP32)) -> 0.67301167 | BR32: ==IF(BJ32=0,0,BQ32/LN(4)*100) -> 48.54753 | BS32: ==_xlfn.XLOOKUP(B32,点位均值!$A:$A,点位均值!$B:$B,"无匹配") -> 2.1831762 | BT32: ==_xlfn.XLOOKUP(B32,点位均值!$A:$A,点位均值!$C:$C,"无匹配") -> 3.1449608
A33: 26 | B33: 上海市徐汇区湖南路街道五原路98号 | C33: A2 商业界面 | D33: B1d 整体后退 | E33: B2d 完全开敞 | I33: C3 建筑尺度（整栋建筑） | J33: D2 行道树；D4 电线杆 | K33: ==IF(TRIM(CLEAN(J33))="","",(IF(ISNUMBER(SEARCH("公共座椅",TRIM(CLEAN(J33)))),2,0)+IF(ISNUMBER(SEARCH("行道树",TRIM(CLEAN(J33)))),1,0)+IF(ISNUMBER(SEARCH("花坛",TRIM(CLEAN(J33)))),0.75,0)+IF(ISNUMBER(SEARCH("电线杆",TRIM(CLEAN(J33)))),0.4,0)+IF(ISNUMBER(SEARCH("路灯",TRIM(CLEAN(J33)))),0.45,0)+IF(ISNUMBER(SEARCH("共享单车",TRIM(CLEAN(J33)))),0.35,0)+IF(ISNUMBER(SEARCH("垃圾桶",TRIM(CLEAN(J33)))),-0.5,0))/(1+LN(1+(LEN(TRIM(CLEAN(J33)))-LEN(SUBSTITUTE(TRIM(CLEAN(J33)),";",""))+1)))) -> 0.82686255 | L33: 8 | M33: 0 | N33: 10 | O33: 餐饮/饮品 | P33: 1 | Q33: 5 | R33: 200 | S33: 10 | T33: 7 | U33: 5 | V33: 5 | W33: 5 | X33: 左侧有连续界面（商店） | Z33: 5 | AA33: 3 | AB33: 5 | AE33: 树木；建筑 | AF33: 50 | AG33: 3 | AH33: 3 | AI33: 3 | AJ33: 1 | AK33: 0 | AL33: 3 | AM33: 0 | AN33: 3 | AO33: 0 | AP33: 0 | AQ33: 1 | AR33: 2 | AS33: 0 | AT33: 2 | AU33: 1 | AV33: 0 | AW33: 0 | AX33: 0 | AY33: 3 | AZ33: 0 | BA33: 0 | BB33: 0 | BC33: 0 | BD33: 0 | BE33: 0 | BF33: 0 | BG33: 0 | BH33: 0 | BI33: 0 | BJ33: ==AI33 -> 3 | BK33: ==BJ33/N33 -> 0.3 | BL33: ==AL33/AI33 -> 1 | BM33: ==IF(BJ33=0,0,AM33/BJ33) -> 0 | BN33: ==IF(BJ33=0,0,AN33/BJ33) -> 1 | BO33: ==IF(BJ33=0,0,AO33/BJ33) -> 0 | BP33: ==IF(BJ33=0,0,AP33/BJ33) -> 0 | BQ33: ==-IF(BM33=0,0,BM33*LN(BM33))-IF(BN33=0,0,BN33*LN(BN33))-IF(BO33=0,0,BO33*LN(BO33))-IF(BP33=0,0,BP33*LN(BP33)) -> 0 | BR33: ==IF(BJ33=0,0,BQ33/LN(4)*100) -> 0 | BS33: ==_xlfn.XLOOKUP(B33,点位均值!$A:$A,点位均值!$B:$B,"无匹配") -> 0.1 | BT33: ==_xlfn.XLOOKUP(B33,点位均值!$A:$A,点位均值!$C:$C,"无匹配") -> 4.0031332
A34: 55 | B34: 上海市徐汇区湖南路街道延庆路147号 | C34: A2 商业界面 | D34: B1b 区域后退 | E34: B2b 橱窗 | G34: B3b-ii 招牌 | I34: C2 开间尺度（单个店面或小片连续界面） | J34: D2 行道树；D4 电线杆 | K34: ==IF(TRIM(CLEAN(J34))="","",(IF(ISNUMBER(SEARCH("公共座椅",TRIM(CLEAN(J34)))),2,0)+IF(ISNUMBER(SEARCH("行道树",TRIM(CLEAN(J34)))),1,0)+IF(ISNUMBER(SEARCH("花坛",TRIM(CLEAN(J34)))),0.75,0)+IF(ISNUMBER(SEARCH("电线杆",TRIM(CLEAN(J34)))),0.4,0)+IF(ISNUMBER(SEARCH("路灯",TRIM(CLEAN(J34)))),0.45,0)+IF(ISNUMBER(SEARCH("共享单车",TRIM(CLEAN(J34)))),0.35,0)+IF(ISNUMBER(SEARCH("垃圾桶",TRIM(CLEAN(J34)))),-0.5,0))/(1+LN(1+(LEN(TRIM(CLEAN(J34)))-LEN(SUBSTITUTE(TRIM(CLEAN(J34)),";",""))+1)))) -> 0.82686255 | L34: 39 | M34: 0 | N34: 89 | O34: 其他 | P34: 1 | Q34: 1 | R34: 0 | S34: 0 | T34: 0 | U34: 3.5 | V34: 3 | W34: 3 | X34: 界面连续无分隔 | Y34: 7ee08960219183f8c9c99be9fe21e3d5.jpg | Z34: 2 | AA34: 2 | AB34: 3.5 | AC34: 无座位，站立停留拍照打卡，无围合、抬升、无特殊铺地 | AD34: 7ee08960219183f8c9c99be9fe21e3d5.jpg | AE34: 其他 | AF34: 0 | AG34: 3.5 | AH34: 3.5 | AI34: 4 | AJ34: 2 | AK34: 0 | AL34: 4 | AM34: 0 | AN34: 4 | AO34: 0 | AP34: 0 | AQ34: 2 | AR34: 2 | AS34: 0 | AT34: 0 | AU34: 4 | AV34: 0 | AW34: 0 | AX34: 0 | AY34: 4 | AZ34: 0 | BA34: 0 | BB34: 0 | BC34: 0 | BD34: 0 | BE34: 0 | BF34: 0 | BG34: 0 | BH34: 2 | BI34: 0 | BJ34: ==AI34 -> 4 | BK34: ==BJ34/N34 -> 0.04494382 | BL34: ==AL34/AI34 -> 1 | BM34: ==IF(BJ34=0,0,AM34/BJ34) -> 0 | BN34: ==IF(BJ34=0,0,AN34/BJ34) -> 1 | BO34: ==IF(BJ34=0,0,AO34/BJ34) -> 0 | BP34: ==IF(BJ34=0,0,AP34/BJ34) -> 0 | BQ34: ==-IF(BM34=0,0,BM34*LN(BM34))-IF(BN34=0,0,BN34*LN(BN34))-IF(BO34=0,0,BO34*LN(BO34))-IF(BP34=0,0,BP34*LN(BP34)) -> 0 | BR34: ==IF(BJ34=0,0,BQ34/LN(4)*100) -> 0 | BS34: ==_xlfn.XLOOKUP(B34,点位均值!$A:$A,点位均值!$B:$B,"无匹配") -> 0.56674938 | BT34: ==_xlfn.XLOOKUP(B34,点位均值!$A:$A,点位均值!$C:$C,"无匹配") -> 4.1065274
A35: 61 | B35: 上海市静安区南京西路街道富民路160号 | C35: A2 商业界面 | D35: B1a 无后退 | E35: B2d 完全开敞 | F35: B3a-ii 外摆在外侧 | I35: C2 开间尺度（单个店面或小片连续界面） | J35: D2 行道树；D4 电线杆 | K35: ==IF(TRIM(CLEAN(J35))="","",(IF(ISNUMBER(SEARCH("公共座椅",TRIM(CLEAN(J35)))),2,0)+IF(ISNUMBER(SEARCH("行道树",TRIM(CLEAN(J35)))),1,0)+IF(ISNUMBER(SEARCH("花坛",TRIM(CLEAN(J35)))),0.75,0)+IF(ISNUMBER(SEARCH("电线杆",TRIM(CLEAN(J35)))),0.4,0)+IF(ISNUMBER(SEARCH("路灯",TRIM(CLEAN(J35)))),0.45,0)+IF(ISNUMBER(SEARCH("共享单车",TRIM(CLEAN(J35)))),0.35,0)+IF(ISNUMBER(SEARCH("垃圾桶",TRIM(CLEAN(J35)))),-0.5,0))/(1+LN(1+(LEN(TRIM(CLEAN(J35)))-LEN(SUBSTITUTE(TRIM(CLEAN(J35)),";",""))+1)))) -> 0.82686255 | L35: 12.8 | M35: 0 | N35: 21.3 | O35: 餐饮/饮品；零售 | P35: 2 | Q35: 4 | R35: 67 | S35: 100 | T35: 6 | U35: 3.3 | V35: 4.7 | W35: 4.7 | X35: 界面连续均为店铺 | Y35: 373a30ad51ed4443ec01ce20a405f244.jpg | Z35: 4.3 | AA35: 3.3 | AB35: 3.3 | AC35: 座位设置在马路边，无特殊铺地、无围合、无抬升 | AD35: 373a30ad51ed4443ec01ce20a405f244.jpg | AE35: 其他 | AF35: 10 | AG35: 4 | AH35: 4 | AI35: 6 | AJ35: 3 | AK35: 0 | AL35: 6 | AM35: 0 | AN35: 6 | AO35: 0 | AP35: 0 | AQ35: 0 | AR35: 6 | AS35: 0 | AT35: 6 | AU35: 0 | AV35: 0 | AW35: 0 | AX35: 6 | AY35: 0 | AZ35: 6 | BA35: 0 | BB35: 0 | BC35: 0 | BD35: 0 | BE35: 0 | BF35: 0 | BG35: 0 | BH35: 0 | BI35: 0 | BJ35: ==AI35 -> 6 | BK35: ==BJ35/N35 -> 0.28169014 | BL35: ==AL35/AI35 -> 1 | BM35: ==IF(BJ35=0,0,AM35/BJ35) -> 0 | BN35: ==IF(BJ35=0,0,AN35/BJ35) -> 1 | BO35: ==IF(BJ35=0,0,AO35/BJ35) -> 0 | BP35: ==IF(BJ35=0,0,AP35/BJ35) -> 0 | BQ35: ==-IF(BM35=0,0,BM35*LN(BM35))-IF(BN35=0,0,BN35*LN(BN35))-IF(BO35=0,0,BO35*LN(BO35))-IF(BP35=0,0,BP35*LN(BP35)) -> 0 | BR35: ==IF(BJ35=0,0,BQ35/LN(4)*100) -> 0 | BS35: ==_xlfn.XLOOKUP(B35,点位均值!$A:$A,点位均值!$B:$B,"无匹配") -> 1.3282878 | BT35: ==_xlfn.XLOOKUP(B35,点位均值!$A:$A,点位均值!$C:$C,"无匹配") -> 2.9691906
A36: 64 | B36: 上海市静安区南京西路街道巨鹿路542号 | C36: A2 商业界面 | D36: B1b 区域后退 | E36: B2d 完全开敞 | F36: B3a-i 外摆在内侧 | I36: C2 开间尺度（单个店面或小片连续界面） | J36: D2 行道树；D4 电线杆 | K36: ==IF(TRIM(CLEAN(J36))="","",(IF(ISNUMBER(SEARCH("公共座椅",TRIM(CLEAN(J36)))),2,0)+IF(ISNUMBER(SEARCH("行道树",TRIM(CLEAN(J36)))),1,0)+IF(ISNUMBER(SEARCH("花坛",TRIM(CLEAN(J36)))),0.75,0)+IF(ISNUMBER(SEARCH("电线杆",TRIM(CLEAN(J36)))),0.4,0)+IF(ISNUMBER(SEARCH("路灯",TRIM(CLEAN(J36)))),0.45,0)+IF(ISNUMBER(SEARCH("共享单车",TRIM(CLEAN(J36)))),0.35,0)+IF(ISNUMBER(SEARCH("垃圾桶",TRIM(CLEAN(J36)))),-0.5,0))/(1+LN(1+(LEN(TRIM(CLEAN(J36)))-LEN(SUBSTITUTE(TRIM(CLEAN(J36)),";",""))+1)))) -> 0.82686255 | L36: 18 | M36: 1 | N36: 21.3 | O36: 餐饮/饮品 | P36: 3 | Q36: 2 | R36: 87 | S36: 100 | T36: 3 | U36: 5 | V36: 4 | W36: 5 | X36: 界面断裂，为居住小区入口 | Y36: 739.jpg | Z36: 4 | AA36: 3 | AB36: 5 | AC36: 座位停留处有抬升、有围合、存在区别于人行道的铺地 | AD36: 739.jpg | AE36: 树木；建筑 | AF36: 70 | AG36: 4 | AH36: 3 | AI36: 3 | AJ36: 1 | AK36: 1 | AL36: 2 | AM36: 0 | AN36: 0 | AO36: 3 | AP36: 0 | AQ36: 2 | AR36: 1 | AS36: 0 | AT36: 2 | AU36: 1 | AV36: 1 | AW36: 0 | AX36: 0 | AY36: 0 | AZ36: 2 | BA36: 0 | BB36: 2 | BC36: 0 | BD36: 0 | BE36: 0 | BF36: 0 | BG36: 0 | BH36: 0 | BI36: 0 | BJ36: ==AI36 -> 3 | BK36: ==BJ36/N36 -> 0.14084507 | BL36: ==AL36/AI36 -> 0.66666667 | BM36: ==IF(BJ36=0,0,AM36/BJ36) -> 0 | BN36: ==IF(BJ36=0,0,AN36/BJ36) -> 0 | BO36: ==IF(BJ36=0,0,AO36/BJ36) -> 1 | BP36: ==IF(BJ36=0,0,AP36/BJ36) -> 0 | BQ36: ==-IF(BM36=0,0,BM36*LN(BM36))-IF(BN36=0,0,BN36*LN(BN36))-IF(BO36=0,0,BO36*LN(BO36))-IF(BP36=0,0,BP36*LN(BP36)) -> 0 | BR36: ==IF(BJ36=0,0,BQ36/LN(4)*100) -> 0 | BS36: ==_xlfn.XLOOKUP(B36,点位均值!$A:$A,点位均值!$B:$B,"无匹配") -> 2.1799007 | BT36: ==_xlfn.XLOOKUP(B36,点位均值!$A:$A,点位均值!$C:$C,"无匹配") -> 2.1420366
A37: 71 | B37: 上海市黄浦区瑞金二路街道茂名南路132号 | C37: A2 商业界面 | D37: B1a 无后退 | E37: B2b 橱窗 | F37: B3a-ii 外摆在外侧 | I37: C2 开间尺度（单个店面或小片连续界面） | J37: D2 行道树；D4 电线杆 | K37: ==IF(TRIM(CLEAN(J37))="","",(IF(ISNUMBER(SEARCH("公共座椅",TRIM(CLEAN(J37)))),2,0)+IF(ISNUMBER(SEARCH("行道树",TRIM(CLEAN(J37)))),1,0)+IF(ISNUMBER(SEARCH("花坛",TRIM(CLEAN(J37)))),0.75,0)+IF(ISNUMBER(SEARCH("电线杆",TRIM(CLEAN(J37)))),0.4,0)+IF(ISNUMBER(SEARCH("路灯",TRIM(CLEAN(J37)))),0.45,0)+IF(ISNUMBER(SEARCH("共享单车",TRIM(CLEAN(J37)))),0.35,0)+IF(ISNUMBER(SEARCH("垃圾桶",TRIM(CLEAN(J37)))),-0.5,0))/(1+LN(1+(LEN(TRIM(CLEAN(J37)))-LEN(SUBSTITUTE(TRIM(CLEAN(J37)),";",""))+1)))) -> 0.82686255 | L37: 7 | M37: 0 | N37: 8 | O37: 餐饮/饮品 | P37: 1 | Q37: 2 | T37: 20 | U37: 4 | V37: 4 | W37: 3 | Z37: 2 | AA37: 1 | AB37: 4 | AE37: 树木；建筑 | AF37: 80 | AG37: 2 | AH37: 4 | AI37: 17 | AJ37: 3 | AK37: 8 | AL37: 9 | AM37: 0 | AN37: 7 | AO37: 10 | AP37: 0 | AQ37: 9 | AR37: 8 | AS37: 0 | AT37: 12 | AU37: 5 | AV37: 0 | AW37: 1 | AX37: 11 | AY37: 1 | AZ37: 2 | BA37: 0 | BB37: 3 | BC37: 2 | BD37: 0 | BE37: 0 | BF37: 0 | BG37: 0 | BH37: 0 | BI37: 1 | BJ37: ==AI37 -> 17 | BK37: ==BJ37/N37 -> 2.125 | BL37: ==AL37/AI37 -> 0.52941176 | BM37: ==IF(BJ37=0,0,AM37/BJ37) -> 0 | BN37: ==IF(BJ37=0,0,AN37/BJ37) -> 0.41176471 | BO37: ==IF(BJ37=0,0,AO37/BJ37) -> 0.58823529 | BP37: ==IF(BJ37=0,0,AP37/BJ37) -> 0 | BQ37: ==-IF(BM37=0,0,BM37*LN(BM37))-IF(BN37=0,0,BN37*LN(BN37))-IF(BO37=0,0,BO37*LN(BO37))-IF(BP37=0,0,BP37*LN(BP37)) -> 0.6774944 | BR37: ==IF(BJ37=0,0,BQ37/LN(4)*100) -> 48.870891 | BS37: ==_xlfn.XLOOKUP(B37,点位均值!$A:$A,点位均值!$B:$B,"无匹配") -> 1.0262735 | BT37: ==_xlfn.XLOOKUP(B37,点位均值!$A:$A,点位均值!$C:$C,"无匹配") -> 2.1496391
A38: 97 | B38: 上海市徐汇区天平路街道陕西南路287弄12号 | C38: A4 基础设施界面 | D38: B1a 无后退 | E38: B2b 橱窗 | I38: C4 组团尺度（院落或街区） | J38: D2 行道树；D4 电线杆 | K38: ==IF(TRIM(CLEAN(J38))="","",(IF(ISNUMBER(SEARCH("公共座椅",TRIM(CLEAN(J38)))),2,0)+IF(ISNUMBER(SEARCH("行道树",TRIM(CLEAN(J38)))),1,0)+IF(ISNUMBER(SEARCH("花坛",TRIM(CLEAN(J38)))),0.75,0)+IF(ISNUMBER(SEARCH("电线杆",TRIM(CLEAN(J38)))),0.4,0)+IF(ISNUMBER(SEARCH("路灯",TRIM(CLEAN(J38)))),0.45,0)+IF(ISNUMBER(SEARCH("共享单车",TRIM(CLEAN(J38)))),0.35,0)+IF(ISNUMBER(SEARCH("垃圾桶",TRIM(CLEAN(J38)))),-0.5,0))/(1+LN(1+(LEN(TRIM(CLEAN(J38)))-LEN(SUBSTITUTE(TRIM(CLEAN(J38)),";",""))+1)))) -> 0.82686255 | L38: 12 | M38: 0 | N38: 20 | O38: 零售 | P38: 2 | Q38: 4 | R38: 150 | S38: 10 | T38: 10 | U38: 4 | V38: 2 | W38: 2 | X38: 店铺在二楼，通过窄入口上楼，楼下大橱窗有长椅，店铺暂时歇业 | Z38: 4 | AA38: 4 | AB38: 5 | AC38: 地面平整，铺地有颜色变化 | AE38: 树木；建筑 | AF38: 90 | AG38: 4 | AH38: 3 | AI38: 7 | AJ38: 2 | AK38: 2 | AL38: 5 | AM38: 0 | AN38: 1 | AO38: 4 | AP38: 2 | AQ38: 2 | AR38: 5 | AS38: 0 | AT38: 4 | AU38: 3 | AV38: 0 | AW38: 1 | AX38: 0 | AY38: 0 | AZ38: 5 | BA38: 0 | BB38: 0 | BC38: 5 | BD38: 0 | BE38: 0 | BF38: 0 | BG38: 0 | BH38: 0 | BI38: 0 | BJ38: ==AI38 -> 7 | BK38: ==BJ38/N38 -> 0.35 | BL38: ==AL38/AI38 -> 0.71428571 | BM38: ==IF(BJ38=0,0,AM38/BJ38) -> 0 | BN38: ==IF(BJ38=0,0,AN38/BJ38) -> 0.14285714 | BO38: ==IF(BJ38=0,0,AO38/BJ38) -> 0.57142857 | BP38: ==IF(BJ38=0,0,AP38/BJ38) -> 0.28571429 | BQ38: ==-IF(BM38=0,0,BM38*LN(BM38))-IF(BN38=0,0,BN38*LN(BN38))-IF(BO38=0,0,BO38*LN(BO38))-IF(BP38=0,0,BP38*LN(BP38)) -> 0.95569989 | BR38: ==IF(BJ38=0,0,BQ38/LN(4)*100) -> 68.939175 | BS38: ==_xlfn.XLOOKUP(B38,点位均值!$A:$A,点位均值!$B:$B,"无匹配") -> 3.0689472 | BT38: ==_xlfn.XLOOKUP(B38,点位均值!$A:$A,点位均值!$C:$C,"无匹配") -> 1.181947
